Workbook

Sheet Alt 1 - Conventional System
C2: Optimistic | D2: Base | E2: Pessimistic | G2: Alternative I - Conventional Checkout System | J2: Hardware Cost: | K2: https://qashier.com/sg/product-category/accessories/
B3: Initial One-Off Grant Subsidy (%) | C3: 0.5 | D3: 0.25 | E3: 0 | G3: MARR | H3: 0.1 | J3: Software Cost: | K3: https://qashier.com/sg/software-pricing/
B4: Annual Benefit (%) | C4: 0.17 | D4: 0.085 | E4: 0 | G4: Study Period (years) | H4: 3 | J4: Manpower Cost: | K4: https://sg.indeed.com/jobs?q=Supermarket+Cashier&l=singapore&mna=&=&aceid=&gad_source=1&gclid=Cj0KCQjw2a6wBhCVARIsABPeH1tTloqXXFTRE1Lqn0HInCf26Q-QdfdyuhmoMMoFar2G4mif7wfBkNQaAj3uEALw_wcB&gclsrc=aw.ds&from=mobRdr&utm_source=%2Fm%2F&utm_medium=redir&utm_campaign=dt&vjk=725fbfdeb7984e94
A5: ` | B5: Manpower Duration (hr/year) - 40h/week | C5: =40*52 -> 2080 | D5: =40*52 -> 2080 | E5: =40*52 -> 2080 | G5: Corporate Tax | H5: 0.17
B6: Manpower Cost ($/h) | C6: 8 | D6: 10 | E6: 12 | G6: Annual Sales Volume | H6: 600000
B7: Shrinkage Loss (%) | C7: 0 | D7: 0.00015 | E7: 0.0005
B8: Hardware & Software Cost ($) - per machine | C8: =500+840+910 -> 2250 | D8: =(C8+E8)/2 -> 2644 | E8: =2188+850 -> 3038
B9: Annual Sales ($) | C9: 1800000 | D9: ='Break-Even Analysis'!W4 -> 1061536.6 | E9: 323073.3
B10: Monthly Operation & Maintenance Costs ($) | C10: 100 | D10: =(C10+E10)/2 -> 175 | E10: 250
B11: Market Value (%) | C11: 0.5 | D11: 0.4 | E11: 0.3
B14: CASH FLOW
C16: Optimistic | D16: Base | E16: Pessimistic
B17: Initial Investment - 2 Checkout Lanes | C17: =-(C8*2) -> -4500 | D17: ='Break-Even Analysis'!B4 -> -5466 | E17: =-(E8*2) -> -6076 | F17: (Hardware + Software Cost)*2
B18: Initial One-off Grant Subsidy | C18: =-(C3*C17) -> 2250 | D18: =-(D3*D17) -> 1366.5 | E18: =-(E3*E17) -> 0 | F18: Subsidy Percentage * Investment Cost
B19: Annual Sales Volume | C19: 1800000 | D19: =(C19+E19)/2 -> 1061536.6 | E19: 323073.3
B20: Annual Benefits | C20: =C4*C9 -> 306000 | D20: =D4*D9 -> 90230.615 | E20: =E4*E9 -> 0 | F20: Annual Benefit Percentage * Annual Sales Volume
B21: Operation & Maintenance Costs | C21: =-(C10*12) -> -1200 | D21: =-(D10*12) -> -2100 | E21: =-(E10*12) -> -3000 | F21: Monthly Operation & Maintenance Costs * 12
B22: Manpower Costs | C22: =-(2*C6*C5) -> -33280 | D22: =-(2*D6*D5) -> -41600 | E22: =-(2*E6*E5) -> -49920 | F22: (Salary per Hour * No. of Working Hours per Year)*2
B23: Shrinkage Costs | C23: =C7*C9 -> 0 | D23: =-D7*D9 -> -159.2305 | E23: =-E7*E9 -> -161.53665 | F23: Shrinkage Loss Percentage * Annual Sales Volume
B24: Market Value at EoY 3 | C24: =-(C11*C17) -> 2250 | D24: =-(D11*D17) -> 2186.4 | E24: =-(E11*E17) -> 1822.8 | F24: Market Value Percentage * Investment Cost
B25: Useful Life (years) | C25: 7 | D25: 5 | E25: 3
B28: BASE CASE SCENARIO
C30: (a) | D30: (b) | E30: (c) = (a) - (b) | F30: (d) = -t(c) | G30: (e) = (a) + (d) | H30: (e)/(1+i)^k
B31: End of Year (EoY) | C31: BTCF | D31: Depreciation | E31: Taxable Income | F31: Tax Cashflow | G31: ATCF | H31: PW of ATCF
B32: 0 | C32: =D17+D18 -> -4099.5 | G32: =C32 -> -4099.5 | H32: =G32/((1+$H$3)^B32) -> -4099.5
B33: 1 | C33: =SUM(D20:D23) -> 46371.385 | D33: =-($D$17+$D$18)/3 -> 1366.5 | E33: =C33-D33 -> 45004.885 | F33: =-17%*E33 -> -7650.8304 | G33: =C33+F33 -> 38720.554 | H33: =G33/((1+$H$3)^B33) -> 35200.504
B34: 2 | C34: =SUM(D20:D23) -> 46371.385 | D34: =-($D$17+$D$18)/3 -> 1366.5 | E34: =C34-D34 -> 45004.885 | F34: =-17%*E34 -> -7650.8304 | G34: =C34+F34 -> 38720.554 | H34: =G34/((1+$H$3)^B34) -> 32000.458
B35: 3 | C35: =SUM(D20:D23) -> 46371.385 | D35: =-($D$17+$D$18)/3 -> 1366.5 | E35: =C35-D35 -> 45004.885 | F35: =-17%*E35 -> -7650.8304 | G35: =C35+F35 -> 38720.554 | H35: =G35/((1+$H$3)^B35) -> 29091.326
B36: 3 | C36: =D24 -> 2186.4 | E36: =C36-D36 -> 2186.4 | F36: =-C36*H5 -> -371.688 | G36: =C36+F36 -> 1814.712 | H36: =G36/((1+$H$3)^B36) -> 1363.42
G38: PW of ATCF | H38: =SUM(H32:H36) -> 93556.208
G39: AW of ATCF | H39: =PMT(H3, H4, -H38, 0, 0) -> 37620.336

Sheet Alt 1 - Tornado Chart
A1: SensIt 1.53 Trial Version, Only For Evaluation
A2: Many Inputs, One Output
A3: Single-Factor Sensitivity Analysis
E6: Present Worth (PW)
B7: Corresponding Input Value | E7: Output Value | I7: Percent
A8: Input Variable | B8: Low Output | C8: Base Case | D8: High Output | E8: Low | F8: Base | G8: High | H8: Swing | I8: Swing^2
A9: Annual benefits | B9: 0 | C9: 90230.615 | D9: 306000 | E9: -92687.65 | F9: 93556.208 | G9: 538923.02 | H9: 631610.67 | I9: 0.99700291
A10: Manpower costs | B10: -49920 | C10: -41600 | D10: -33280 | E10: 76383 | F10: 93556.208 | G10: 110729.41 | H10: 34346.41 | I10: 0.0029482222
A11: O&M costs | B11: -3000 | C11: -2100 | D11: -1200 | E11: 91698.53 | F11: 93556.208 | G11: 95413.89 | H11: 3715.36 | I11: 3.4498428e-05
A12: One-off subsidy | B12: 0 | C12: 1366.5 | D12: 2250 | E12: 92382.28 | F12: 93556.208 | G12: 94315.2 | H12: 1932.92 | I12: 9.337385e-06
A13: Initial setup costs | B13: -6076 | C13: -5466 | D13: -4500 | E13: 93032.17 | F13: 93556.208 | G13: 94386.08 | H13: 1353.91 | I13: 4.5811773e-06
A14: Shrinkage costs | B14: -161.5367 | C14: -159.2305 | D14: 0 | E14: 93551.45 | F14: 93556.208 | G14: 93884.87 | H14: 333.42 | I14: 2.7783106e-07
A15: MV at EOY 3 | B15: 1822.8 | C15: 2186.4 | D15: 2250 | E15: 93329.47 | F15: 93556.208 | G15: 93595.87 | H15: 266.4 | I15: 1.7736419e-07
A16: Sales | B16: 1800000 | C16: 1061536.6 | D16: 323073.3 | E16: 93556.21 | F16: 93556.208 | G16: 93556.21 | H16: 0 | I16: 0
N19: 3 Key Factors of Uncertainty:
N20: Annual Benefits
N21: Manpower Costs
N22: Operation & Maintenance Costs
A40: This Version Not Licensed For Commercial Or Student Use | I40: TreePlan.com

Sheet Alt 2 - Self-checkout System
C2: Optimistic | D2: Base | E2: Pessimistic | G2: Alternative II - Self-checkout System
B3: Initial One-Off Grant Subsidy (%) | C3: 0.5 | D3: 0.25 | E3: 0 | G3: After-Tax MARR | H3: 0.1
B4: Annual Benefit (%) | C4: 0.3 | D4: 0.15 | E4: 0 | G4: Study Period (years) | H4: 3
B5: Manpower Duration (hr/year) - 40h/week | C5: 2080 | D5: =40*52 -> 2080 | E5: 2080 | G5: Annual sales volume | H5: 600000
B6: Manpower Cost ($/h) | C6: 8 | D6: 10 | E6: 12 | G6: Corporate tax | H6: 0.17
B7: Shrinkage Loss (%) | C7: 0 | D7: 0.035 | E7: 0.07 | G7: Assumption | H7: Co-Termination
B8: Annual Sales ($) | C8: 1800000 | D8: =AVERAGE(C8,E8) -> 1061536.6 | E8: 323073.3
B9: Market Value (%) | C9: 0.5 | D9: 0.4 | E9: 0.3
B12: CASH FLOW
C14: Optimistic | D14: Base | E14: Pessimistic
B15: Initial Investment | C15: -110000 | D15: -125000 | E15: -150000
B16: Initial One-off Grant Subsidy | C16: =-(C3*C15) -> 55000 | D16: =-(D3*D15) -> 31250 | E16: =(E3*E15) -> 0 | F16: Subsidy Percentage * Investment Cost
B17: Annual Sales Volume | C17: =C8 -> 1800000 | D17: =D8 -> 1061536.6 | E17: =E8 -> 323073.3
B18: Annual Benefit | C18: =C4*C8 -> 540000 | D18: =D4*D8 -> 159230.5 | E18: =E4*E8 -> 0 | F18: Annual Benefit Percentage * Annual Sales Volume
B19: Operation & Maintenance Cost | C19: -20352 | D19: -20675.05 | E19: -21690.3
B20: Manpower Cost (Full-time Associate x1) | C20: =-C6*C5 -> -16640 | D20: =-D5*D6 -> -20800 | E20: =-E5*E6 -> -24960 | F20: Salary per Hour * No. of Working Hours per Year
B21: Shrinkage Costs | C21: =C7*C8 -> 0 | D21: =-(D7*D8) -> -37153.783 | E21: =-(E7*E8) -> -22615.131 | F21: Shrinkage Loss Percentage * Annual Sales Volume
B22: Market Value at EoY 3 | C22: =-(C9*C15) -> 55000 | D22: =-(D9*D15) -> 50000 | E22: =-(E9*E15) -> 45000 | F22: Market Value Percentage * Investment Cost
B23: Useful Life (years) | C23: 7 | D23: 5 | E23: 3
B26: BASE CASE SCENARIO
C28: (a) | D28: (b) | E28: (c) = (a) - (b) | F28: (d) = -t(c) | G28: (e) = (a) + (d) | H28: (e)/(1+i)^k
B29: End of Year | C29: BTCF | D29: Depreciation | E29: Taxable Income | F29: Tax Cashflow | G29: ATCF | H29: PW of ATCF
B30: 0 | C30: =D15+D16 -> -93750 | G30: =C30 -> -93750 | H30: =G30/((1+$H$3)^B30) -> -93750
B31: 1 | C31: =SUM(D18:D21) -> 80601.665 | D31: =-$C$30/3 -> 31250 | E31: =C31-D31 -> 49351.665 | F31: =-0.17*E31 -> -8389.783 | G31: =C31+F31 -> 72211.882 | H31: =G31/((1+$H$3)^B31) -> 65647.165
B32: 2 | C32: =SUM(D18:D21) -> 80601.665 | D32: =-$C$30/3 -> 31250 | E32: =C32-D32 -> 49351.665 | F32: =-0.17*E32 -> -8389.783 | G32: =C32+F32 -> 72211.882 | H32: =G32/((1+$H$3)^B32) -> 59679.241
B33: 3 | C33: =SUM(D18:D21) -> 80601.665 | D33: =-$C$30/3 -> 31250 | E33: =C33-D33 -> 49351.665 | F33: =-0.17*E33 -> -8389.783 | G33: =C33+F33 -> 72211.882 | H33: =G33/((1+$H$3)^B33) -> 54253.856
B34: 3 | C34: =D22 -> 50000 | E34: =C34 -> 50000 | F34: =-C34*H6 -> -8500 | G34: =C34+F34 -> 41500 | H34: =G34/((1+$H$3)^B34) -> 31179.564
G36: PW of ATCF | H36: =SUM(H30:H34) -> 117009.83
G37: AW of ATCF | H37: =PMT(H3, H4, -H36, 0, 0) -> 47051.383

Sheet Alt 2 - Tornado Chart
A1: SensIt 1.53 Trial Version, Only For Evaluation
A2: Many Inputs, One Output
A3: Single-Factor Sensitivity Analysis
E6: Present Worth (PW)
B7: Corresponding Input Value | E7: Output Value | I7: Percent
A8: Input Variable | B8: Low Output | C8: Base Case | D8: High Output | E8: Low | F8: Base | G8: High | H8: Swing | I8: Swing^2
A9: Sales | B9: 323073.3 | C9: 1061536.6 | D9: 1800000 | E9: -71781.12 | F9: 111878.33 | G9: 295537.77 | H9: 367318.89 | I9: 0.95799237
A10: One-off subsidy | B10: 0 | C10: 31250 | D10: 55000 | E10: 80628.33 | F10: 111878.33 | G10: 135628.33 | H10: 55000 | I10: 0.021478349
A11: Initial setup costs | B11: -150000 | C11: -125000 | D11: -110000 | E11: 86878.33 | F11: 111878.33 | G11: 126878.33 | H11: 40000 | I11: 0.011360449
A12: Shrinkage costs | B12: -22615.131 | C12: -21000 | D12: 0 | E12: 109507.07 | F12: 111878.33 | G12: 142709.51 | H12: 33202.44 | I12: 0.0078273639
A13: Manpower costs | B13: -24960 | C13: -20800 | D13: -16640 | E13: 105160.06 | F13: 111878.33 | G13: 118596.59 | H13: 13436.53 | I13: 0.0012818871
A14: MV at EoY 3 | B14: 45000 | C14: 50000 | D14: 55000 | E14: 110430 | F14: 111878.33 | G14: 113326.65 | H14: 2896.65 | I14: 5.9575483e-05
A15: Annual benefits | B15: 0 | C15: 159230.5 | D15: 540000 | E15: 111878.33 | F15: 111878.33 | G15: 111878.33 | H15: 0 | I15: 0
A16: O&M costs | B16: -20352 | C16: -20675.05 | D16: -21690.3 | E16: 111878.33 | F16: 111878.33 | G16: 111878.33 | H16: 0 | I16: 0
A40: This Version Not Licensed For Commercial Or Student Use | I40: TreePlan.com

Sheet Alt 3 - Checkout-free System
C2: Optimistic | D2: Base | E2: Pessimistic | G2: Alternative III - Checkout-free System / Unmanned Shop
B3: Initial One-Off Grant Subsidy (%) | C3: 0.5 | D3: 0.25 | E3: 0 | G3: After-Tax MARR | H3: 0.1
B4: Annual Benefit (%) | C4: 0.1 | D4: 0.05 | E4: 0 | G4: Study Period (years) | H4: 3
B5: Manpower Duration (hr/year) - 4h/day | C5: =4*365 -> 1460 | D5: =4*365 -> 1460 | E5: =4*365 -> 1460 | G5: Corporate Tax | H5: 0.17
B6: Manpower Cost ($/h) | C6: 8 | D6: 9 | E6: 10 | G6: Assumption | H6: Co-Termination
B7: Shrinkage Loss (%) | C7: 0 | D7: 0.005 | E7: 0.01
B8: Annual Sales (SGD$) | C8: 1800000 | D8: =AVERAGE(C8,E8) -> 1061536.6 | E8: 323073.3
B9: Hours in a Year (hr) - 365 days | C9: =24*365 -> 8760 | D9: =24*365 -> 8760 | E9: =24*365 -> 8760
B10: Energy Usage (kWh) | C10: 0.5 | D10: 1 | E10: 1.5
B11: Electricity Tariff ($/kWh) | C11: =29.89/100 -> 0.2989 | D11: =29.89/100 -> 0.2989 | E11: =29.89/100 -> 0.2989
B12: Market Value (%) | C12: 0.6 | D12: 0.5 | E12: 0.4
B15: OPERATION & MAINTENANCE COST | MANPOWER COST
C17: Optimistic | D17: Base | E17: Pessimistic
B18: Maintenance & Repairs Cost | C18: =-(15%*C28) -> -270000 | D18: =(C18+E18)/2 -> -248075.65 | E18: =-(70%*E28) -> -226151.31
B19: Utilities Cost | C19: =-(C9*C10*C11) -> -1309.182 | D19: =-(D9*D10*D11) -> -2618.364 | E19: =-(E9*E10*E11) -> -3927.546 | F19: kWh * No. of Hours per Year * Cost per kWh
B20: Manpower Cost (Part-time Associate x1) | C20: =-(C6*C5) -> -11680 | D20: =-(D6*D5) -> -13140 | E20: =-(E6*E5) -> -14600 | F20: Salary per Hour * No. of Hours per Year
B23: CASH FLOW
C25: Optimistic | D25: Base | E25: Pessimistic
B26: Initial Investment | C26: -94900 | D26: ='Break-Even Analysis'!P4 -> -150000 | E26: -1000000
B27: Initial One-off Grant Subsidy | C27: =0.5*-C26 -> 47450 | D27: =0.25*-D26 -> 37500 | E27: =0*E26 -> 0 | F27: Subsidy Percentage * Investment Cost
B28: Annual Sales Volume | C28: 1800000 | D28: ='Break-Even Analysis'!AL4 -> 1061536.6 | E28: 323073.3
B29: Annual Benefit | C29: =C4*C28 -> 180000 | D29: =D4*D28 -> 53076.832 | E29: =E4*E28 -> 0 | F29: Annual Benefit Percentage * Annual Sales Volume
B30: Operation & Maintenance Cost | C30: =SUM(C18:C19) -> -271309.18 | D30: =SUM(D18:D19) -> -250694.02 | E30: =SUM(E18:E19) -> -230078.86 | F30: Maintenance & Repairs Cost + Utilities Cost
B31: Manpower Cost (Part-time Associate x1) | C31: =C20 -> -11680 | D31: =D20 -> -13140 | E31: =E20 -> -14600 | F31: Salary per Hour * No. of Hours per Year
B32: Shrinkage Cost | C32: =0*-C28 -> 0 | D32: =0.005*-D28 -> -5307.6833 | E32: =0.01*-E28 -> -3230.733 | F32: Shrinkage Loss Percentage * Annual Sales Volume
B33: Market Value at EoY 3 | C33: =C12*-C26 -> 56940 | D33: =D12*-D26 -> 75000 | E33: =E12*-E26 -> 400000 | F33: Market Value Percentage * Investment Cost
B34: Useful Life (years) | C34: 5 | D34: 4 | E34: 3
B37: BASE CASE SCENARIO
C39: (a) | D39: (b) | E39: (c) = (a) - (b) | F39: (d) = -t(c) | G39: (e) = (a) + (d) | H39: (e)/(1+i)^k
B40: End of Year | C40: BTCF | D40: Depreciation | E40: Taxable Income | F40: Tax Cashflow | G40: ATCF | H40: PW of ATCF
B41: 0 | C41: =SUM(D26:D27) -> -112500 | G41: =C41 -> -112500 | H41: =G41 -> -112500
B42: 1 | C42: =SUM($D$29:$D$32) -> -216064.87 | D42: =-C41/3 -> 37500 | E42: =C42-D42 -> -253564.87 | F42: =-$H$5*E42 -> 43106.028 | G42: =C42+F42 -> -172958.84 | H42: =G42/((1+$H$3)^B42) -> -157235.31
B43: 2 | C43: =SUM($D$29:$D$32) -> -216064.87 | D43: =-C41/3 -> 37500 | E43: =C43-D43 -> -253564.87 | F43: =-$H$5*E43 -> 43106.028 | G43: =C43+F43 -> -172958.84 | H43: =G43/((1+$H$3)^B43) -> -142941.19
B44: 3 | C44: =SUM($D$29:$D$32) -> -216064.87 | D44: =-C41/3 -> 37500 | E44: =C44-D44 -> -253564.87 | F44: =-$H$5*E44 -> 43106.028 | G44: =C44+F44 -> -172958.84 | H44: =G44/((1+$H$3)^B44) -> -129946.54
B45: 3 | C45: =D33 -> 75000 | E45: =D33 -> 75000 | F45: =-$H$5*E45 -> -12750 | G45: =C45+F45 -> 62250 | H45: =G45/((1+$H$3)^B45) -> 46769.346
G47: PW of ATCF | H47: =SUM(H41:H45) -> -495853.69
G48: AW of ATCF | H48: =PMT(H3,H4,-H47, 0,0) -> -199390.11

Sheet Alt 3 - Tornado Chart
A1: SensIt 1.53 Trial Version, Only For Evaluation
A2: Many Inputs, One Output
A3: Single-Factor Sensitivity Analysis
E6: After-Tax PW
B7: Corresponding Input Value | E7: Output Value | I7: Percent
A8: Input Variable | B8: Low Output | C8: Base Case | D8: High Output | E8: Low | F8: Base | G8: High | H8: Swing | I8: Swing^2
A9: Initial Investment | B9: -1000000 | C9: -150000 | D9: -94900 | E9: -1341566.7 | F9: -491566.69 | G9: -436466.69 | H9: 905100 | I9: 0.81479119
A10: Annual Benefit | B10: 0 | C10: 53076.832 | D10: 180000 | E10: -601121.9 | F10: -491566.69 | G10: -229586.21 | H10: 371535.69 | I10: 0.13729486
A11: MV at EoY 3 | B11: 56940 | C11: 75000 | D11: 400000 | E11: -502828.75 | F11: -491566.69 | G11: -288899.52 | H11: 213929.23 | I11: 0.045519077
A12: Initial One-Off Grant Subsidy | B12: 0 | C12: 37500 | D12: 47450 | E12: -529066.69 | F12: -491566.69 | G12: -481616.69 | H12: 47450 | I12: 0.0022393688
A13: Shrinkage Cost | B13: -5307.6833 | C13: -3230.733 | D13: 0 | E13: -495853.69 | F13: -491566.69 | G13: -484898.17 | H13: 10955.52 | I13: 0.00011937659
A14: Manpower Cost | B14: -14600 | C14: -13140 | D14: -11680 | E14: -494580.25 | F14: -491566.69 | G14: -488553.12 | H14: 6027.13 | I14: 3.6130528e-05
A15: Annual Sales | B15: 323073.3 | C15: 1061536.6 | D15: 1800000 | E15: -491566.69 | F15: -491566.69 | G15: -491566.69 | H15: 0 | I15: 0
A16: O&M Cost | B16: -271309.18 | C16: -250694.02 | D16: -230078.86 | E16: -491566.69 | F16: -491566.69 | G16: -491566.69 | H16: 0 | I16: 0
K25: 3 Key Factors of Uncertainty:
K26: Initial investment costs
K27: Annual benefit
K28: MV at EoY 3
A40: This Version Not Licensed For Commercial Or Student Use | I40: TreePlan.com

Sheet One-Way Sensitivity Analysis
B2: Alternative I (Conventional Checkout System) - Base Model
F4: RANGE DATA | J4: Alternative I - Conventional Checkout System
B5: Factors | D5: Cash Flow ($) | F5: High (Optimistic) | G5: Base | H5: Low (Pessimistic) | J5: MARR | K5: 0.1
B6: Initial Investment | C6: I | D6: -5466 | F6: -4500 | G6: -5466 | H6: -6076 | J6: Study Period (years) | K6: 3
B7: Initial One-Off Grant Subsidy | C7: G | D7: 1366.5 | F7: 2250 | G7: 1366.5 | H7: 0 | J7: Corporate Tax | K7: 0.17
B8: Annual Benefit | C8: B | D8: 90230.615 | F8: 306000 | G8: 90230.615 | H8: 0 | J8: Annual Sales Volume | K8: 600000
B9: O&M Cost | C9: C | D9: -2100 | F9: -1200 | G9: -2100 | H9: -3000
B10: Manpower Cost | C10: M | D10: -41600 | F10: -33280 | G10: -41600 | H10: -49920
B11: Shrinkage Cost | C11: S | D11: -159.2305 | F11: 0 | G11: -159.2305 | H11: -161.53665
B12: MV at EoY 3 | C12: M | D12: 2186.4 | F12: 2250 | G12: 2186.4 | H12: 1822.8
B13: Useful Life (years) | C13: L | D13: =G13 -> 5 | F13: 3 | G13: 5 | H13: 7
B15: Present Worth (PW) | C15: 93556.208
B16: Annual Worth (AW) | C16: 37620.336
B18: After-Tax Cash Flow Analysis | C18: 0 | D18: 1 | E18: 2 | F18: 3
B19: BTCF
B20: Investment Cost / Salvage Value | C20: =D6+D7 -> -4099.5 | F20: =D12 -> 2186.4
B21: Annual Benefit | D21: =$D$8 -> 90230.615 | E21: =$D$8 -> 90230.615 | F21: =$D$8 -> 90230.615
B22: Annual O&M Cost | D22: =$D$9 -> -2100 | E22: =$D$9 -> -2100 | F22: =$D$9 -> -2100
B23: Annual Manpower Cost | D23: =$D$10 -> -41600 | E23: =$D$10 -> -41600 | F23: =$D$10 -> -41600
B24: Annual Shrinkage Cost | D24: =$D$11 -> -159.2305 | E24: =$D$11 -> -159.2305 | F24: =$D$11 -> -159.2305
B25: Net Income | D25: =SUM(D21:D24) -> 46371.385 | E25: =SUM(E21:E24) -> 46371.385 | F25: =SUM(F20:F24) -> 48557.785
B26: Depreciation | D26: =-$C$20/3 -> 1366.5 | E26: =-$C$20/3 -> 1366.5 | F26: =-$C$20/3 -> 1366.5
B27: Taxable Income | D27: =D25-D26 -> 45004.885 | E27: =E25-E26 -> 45004.885 | F27: =F25-F26 -> 47191.285
B28: Income Tax Cash Flow | D28: =-$K$7*D27 -> -7650.8304 | E28: =-$K$7*E27 -> -7650.8304 | F28: =-$K$7*F27 -> -8022.5184
B29: ATCF | C29: =C20 -> -4099.5 | D29: =D25+D28 -> 38720.554 | E29: =E25+E28 -> 38720.554 | F29: =F25+F28 -> 40535.266
B31: Compacted ATCF Series for IRR() | C31: =C29 -> -4099.5 | D31: =D29 -> 38720.554 | E31: =E29 -> 38720.554 | F31: =F29 -> 40535.266
B32: Afer-Tax PW | C32: =C29+NPV(K5,D29:F29) -> 93556.208 | D32: =IF(C32 >=0, "Feasible", "Infeasible") -> Feasible
B33: After-Tax IRR | D33: =IF(C33>=D8, "Feasible", "Infeasible") -> Infeasible
B36: Alternative II (Checkout-free System / Unmanned Shop) - Base Model
F38: RANGE DATA | J38: Alternative II - Self-checkout System
B39: Factors | D39: Cash Flow ($) | F39: Low (Pessimistic) | G39: Base | H39: High (Optimistic) | J39: After-Tax MARR | K39: 0.1
B40: Initial Investment | C40: I | D40: -125000 | F40: -150000 | G40: -125000 | H40: -110000 | J40: Study Period (years) | K40: 3
B41: Initial One-Off Grant Subsidy | C41: G | D41: 31250 | F41: 0 | G41: 31250 | H41: 55000 | J41: Annual sales volume | K41: 600000
B42: Annual Benefit | C42: B | D42: 159230.5 | F42: =0*F33 -> 0 | G42: 159230.5 | H42: =540000 -> 540000 | J42: Corporate tax | K42: 0.17
B43: O&M Cost | C43: C | D43: -20675.05 | F43: -20352 | G43: -20675.05 | H43: -21690.3 | J43: Assumption | K43: Co-Termination
B44: Manpower Cost | C44: M | D44: -20800 | F44: -24960 | G44: -20800 | H44: -16640
B45: Shrinkage Cost | C45: S | D45: -37153.783 | F45: -22615.131 | G45: -21000 | H45: 0
B46: MV at EoY 3 | C46: M | D46: 50000 | F46: 45000 | G46: 50000 | H46: 55000
B47: Useful Life (years) | C47: L | D47: 5 | F47: 323073.3 | G47: 1061536.6 | H47: 1800000
B49: Present Worth (PW) | C49: 95098.785
...

Sheet Break-Even Analysis
B1: Initial Investment Costs | I1: Initial Investment Costs | P1: Initial Investment Costs | W1: Annual Sales | AD1: Annual Sales | AM1: Annual Sales
A2: Alternative 1 (Conventional Checkout) vs. Alternative 2 (Self-checkout) | H2: Alternative 1 (Conventional Checkout) vs. Alternative 3 (Checkout-free / Unmanned) | O2: Alternative 2 (Self-checkout) vs. Alternative 3 (Checkout-free / Unmanned) | V2: Alternative 1 (Conventional Checkout) vs. Alternative 2 (Self-checkout) | AC2: Alternative 1 (Conventional Checkout) vs. Alternative 3 (Checkout-free / Unmanned) | AL2: Alternative 2 (Self-checkout) vs. Alternative 3 (Checkout-free / Unmanned)
B4: -5466 | I4: -150000 | P4: -150000 | W4: 1061536.6 | AD4: 1061536.6 | AL4: 1061536.6
B6: Initial Cost of Alt 1 | C6: PW(Alt 1) | D6: PW(Alt 2) | I6: Initial Cost of Alt 3 | J6: PW(Alt 3) | K6: PW(Alt 1) | P6: Initial Cost of Alt 3 | Q6: PW(Alt 3) | R6: PW(Alt 2) | W6: Annual Sales of Alt 1 | X6: PW(Alt 1) | Y6: PW(Alt 2) | AD6: Annual Sales of Alt 3 | AE6: PW(Alt 3) | AF6: PW(Alt 1) | AL6: Annual Sales of Alt 3 | AM6: PW(Alt 3) | AN6: PW(Alt 2)
B7: -5466 | C7: ='Alt 1 - Conventional System'!H38 -> 93556.208 | D7: ='Alt 2 - Self-checkout System'!$H$36 -> 117009.83 | I7: -150000 | J7: ='Alt 3 - Checkout-free System'!H47 -> -495853.69 | K7: ='Alt 1 - Conventional System'!$H$38 -> 93556.208 | P7: -150000 | Q7: ='Alt 3 - Checkout-free System'!H47 -> -495853.69 | R7: ='Alt 2 - Self-checkout System'!$H$36 -> 117009.83 | W7: 1061536.6 | X7: ='Alt 1 - Conventional System'!H38 -> 93556.208 | Y7: ='Alt 2 - Self-checkout System'!$H$36 -> 117009.83 | AD7: 1061536.6 | AE7: ='Alt 3 - Checkout-free System'!H47 -> -495853.69 | AF7: ='Alt 1 - Conventional System'!$H$38 -> 93556.208 | AL7: 1061536.6 | AM7: ='Alt 3 - Checkout-free System'!H47 -> -495853.69 | AN7: ='Alt 2 - Self-checkout System'!$H$36 -> 117009.83
B8: =B7+10000 -> 4534 | C8: 97504.93 | D8: ='Alt 2 - Self-checkout System'!$H$36 -> 117009.83 | I8: =I7+100000 -> -50000 | J8: -495853.69 | K8: ='Alt 1 - Conventional System'!$H$38 -> 93556.208 | P8: =P7+100000 -> -50000 | Q8: -462602.38 | R8: ='Alt 2 - Self-checkout System'!$H$36 -> 117009.83 | W8: =W7+20000 -> 1081536.6 | X8: 97058.964 | Y8: ='Alt 2 - Self-checkout System'!$H$36 -> 117009.83 | AD8: =AD7+600000 -> 1661536.6 | AE8: -495853.69 | AF8: ='Alt 1 - Conventional System'!$H$38 -> 93556.208 | AL8: =AL7+1500000 -> 2561536.6 | AM8: -341047.15 | AN8: ='Alt 2 - Self-checkout System'!$H$36 -> 117009.83
B9: =B8+10000 -> 14534 | C9: 101453.65 | D9: ='Alt 2 - Self-checkout System'!$H$36 -> 117009.83 | I9: =I8+100000 -> 50000 | J9: -495853.69 | K9: ='Alt 1 - Conventional System'!$H$38 -> 93556.208 | P9: =P8+100000 -> 50000 | Q9: -429351.06 | R9: ='Alt 2 - Self-checkout System'!$H$36 -> 117009.83 | W9: =W8+20000 -> 1101536.6 | X9: 100561.72 | Y9: ='Alt 2 - Self-checkout System'!$H$36 -> 117009.83 | AD9: =AD8+600000 -> 2261536.6 | AE9: -495853.69 | AF9: ='Alt 1 - Conventional System'!$H$38 -> 93556.208 | AL9: =AL8+1500000 -> 4061536.6 | AM9: -186240.62 | AN9: ='Alt 2 - Self-checkout System'!$H$36 -> 117009.83
B10: =B9+10000 -> 24534 | C10: 105402.38 | D10: ='Alt 2 - Self-checkout System'!$H$36 -> 117009.83 | I10: =I9+100000 -> 150000 | J10: -495853.69 | K10: ='Alt 1 - Conventional System'!$H$38 -> 93556.208 | P10: =P9+100000 -> 150000 | Q10: -396099.75 | R10: ='Alt 2 - Self-checkout System'!$H$36 -> 117009.83 | W10: =W9+20000 -> 1121536.6 | X10: 104064.48 | Y10: ='Alt 2 - Self-checkout System'!$H$36 -> 117009.83 | AD10: =AD9+600000 -> 2861536.6 | AE10: -495853.69 | AF10: ='Alt 1 - Conventional System'!$H$38 -> 93556.208 | AL10: =AL9+1500000 -> 5561536.7 | AM10: -31434.23 | AN10: ='Alt 2 - Self-checkout System'!$H$36 -> 117009.83
B11: =B10+10000 -> 34534 | C11: 109351.1 | D11: ='Alt 2 - Self-checkout System'!$H$36 -> 117009.83 | I11: =I10+100000 -> 250000 | J11: -495853.69 | K11: ='Alt 1 - Conventional System'!$H$38 -> 93556.208 | P11: =P10+100000 -> 250000 | Q11: -362848.43 | R11: ='Alt 2 - Self-checkout System'!$H$36 -> 117009.83 | W11: =W10+20000 -> 1141536.6 | X11: 107567.23 | Y11: ='Alt 2 - Self-checkout System'!$H$36 -> 117009.83 | AD11: =AD10+600000 -> 3461536.6 | AE11: -495853.69 | AF11: ='Alt 1 - Conventional System'!$H$38 -> 93556.208 | AL11: =AL10+1500000 -> 7061536.7 | AM11: 123372.46 | AN11: ='Alt 2 - Self-checkout System'!$H$36 -> 117009.83
B12: =B11+10000 -> 44534 | C12: 113299.82 | D12: ='Alt 2 - Self-checkout System'!$H$36 -> 117009.83 | I12: =I11+100000 -> 350000 | J12: -495853.69 | K12: ='Alt 1 - Conventional System'!$H$38 -> 93556.208 | P12: =P11+100000 -> 350000 | Q12: -329597.12 | R12: ='Alt 2 - Self-checkout System'!$H$36 -> 117009.83 | W12: =W11+20000 -> 1161536.6 | X12: 111069.99 | Y12: ='Alt 2 - Self-checkout System'!$H$36 -> 117009.83 | AD12: =AD11+600000 -> 4061536.6 | AE12: -495853.69 | AF12: ='Alt 1 - Conventional System'!$H$38 -> 93556.208 | AL12: =AL11+1500000 -> 8561536.7 | AM12: 278178.99 | AN12: ='Alt 2 - Self-checkout System'!$H$36 -> 117009.83
B13: =B12+10000 -> 54534 | C13: 117248.54 | D13: ='Alt 2 - Self-checkout System'!$H$36 -> 117009.83 | I13: =I12+100000 -> 450000 | J13: -495853.69 | K13: ='Alt 1 - Conventional System'!$H$38 -> 93556.208 | P13: =P12+100000 -> 450000 | Q13: -296345.81 | R13: ='Alt 2 - Self-checkout System'!$H$36 -> 117009.83 | W13: =W12+20000 -> 1181536.6 | X13: 114572.74 | Y13: ='Alt 2 - Self-checkout System'!$H$36 -> 117009.83 | AD13: =AD12+600000 -> 4661536.7 | AE13: -495853.69 | AF13: ='Alt 1 - Conventional System'!$H$38 -> 93556.208 | AL13: =AL12+1500000 -> 10061537 | AM13: 432985.53 | AN13: ='Alt 2 - Self-checkout System'!$H$36 -> 117009.83
B14: =B13+10000 -> 64534 | C14: 121197.27 | D14: ='Alt 2 - Self-checkout System'!$H$36 -> 117009.83 | W14: =W13+20000 -> 1201536.6 | X14: 118075.5 | Y14: ='Alt 2 - Self-checkout System'!$H$36 -> 117009.83 | AD14: =AD13+600000 -> 5261536.7 | AE14: -495853.69 | AF14: ='Alt 1 - Conventional System'!$H$38 -> 93556.208
B15: =B14+10000 -> 74534 | C15: 125145.99 | D15: ='Alt 2 - Self-checkout System'!$H$36 -> 117009.83 | W15: =W14+20000 -> 1221536.6 | X15: 121578.25 | Y15: ='Alt 2 - Self-checkout System'!$H$36 -> 117009.83 | AD15: =AD14+600000 -> 5861536.7 | AE15: -495853.69 | AF15: ='Alt 1 - Conventional System'!$H$38 -> 93556.208
B16: =B15+10000 -> 84534 | C16: 129094.71 | D16: ='Alt 2 - Self-checkout System'!$H$36 -> 117009.83 | W16: =W15+20000 -> 1241536.6 | X16: 125081.01 | Y16: ='Alt 2 - Self-checkout System'!$H$36 -> 117009.83 | AD16: =AD15+600000 -> 6461536.7 | AE16: -495853.69 | AF16: ='Alt 1 - Conventional System'!$H$38 -> 93556.208
AD17: =AD16+600000 -> 7061536.7 | AE17: -495853.69 | AF17: ='Alt 1 - Conventional System'!$H$38 -> 93556.208
AD18: =AD17+600000 -> 7661536.7 | AE18: -495853.69 | AF18: ='Alt 1 - Conventional System'!$H$38 -> 93556.208
AD19: =AD18+600000 -> 8261536.7 | AE19: -495853.69 | AF19: ='Alt 1 - Conventional System'!$H$38 -> 93556.208
AD20: =AD19+600000 -> 8861536.7 | AE20: -495853.69 | AF20: ='Alt 1 - Conventional System'!$H$38 -> 93556.208
