Workbook
Name check: '10x10'!$B$39
Name consMat: Summary!$C$38:$L$47
Name EV_20: '10x10'!$AG$28:$AG$37
Name m_p0: multInp!$B$9:$K$18
Name m_p1: multInp!$M$9:$V$18
Name m_p10: multInp!$B$74:$K$83
Name m_p11: multInp!$M$74:$V$83
Name m_p12: multInp!$B$87:$K$96
Name m_p13: multInp!$M$87:$V$96
Name m_p14: multInp!$B$100:$K$109
Name m_p15: multInp!$M$100:$V$109
Name m_p16: multInp!$B$113:$K$122
Name m_p17: multInp!$M$113:$V$122
Name m_p18: multInp!$B$126:$K$135
Name m_p19: multInp!$M$126:$V$135
Name m_p2: multInp!$B$22:$K$31
Name m_p20: multInp!$B$139:$K$148
Name m_p3: multInp!$M$22:$V$31
Name m_p4: multInp!$B$35:$K$44
Name m_p5: multInp!$M$35:$V$44
Name m_p6: multInp!$B$48:$K$57
Name m_p7: multInp!$M$48:$V$57
Name m_p8: multInp!$B$61:$K$70
Name m_p9: multInp!$M$61:$V$70
Name m_summary: Summary!$C$38:$J$45
Name Matrix1: 'In1'!$C$79:$L$88
Name Matrix10: 'In10'!$C$79:$L$88
Name Matrix11: 'In11'!$C$79:$L$88
Name Matrix12: 'In12'!$C$79:$L$88
Name Matrix13: 'In13'!$C$79:$L$88
Name Matrix14: 'In14'!$C$79:$L$88
Name Matrix15: 'In15'!$C$79:$L$88
Name Matrix16: 'In16'!$C$79:$L$88
Name Matrix17: 'In17'!$C$79:$L$88
Name Matrix18: 'In18'!$C$79:$L$88
Name Matrix19: 'In19'!$C$79:$L$88
Name Matrix2: 'In2'!$C$79:$L$88
Name Matrix20: 'In20'!$C$79:$L$88
Name Matrix3: 'In3'!$C$79:$L$88
Name Matrix4: 'In4'!$C$79:$L$88
Name Matrix5: 'In5'!$C$79:$L$88
Name Matrix6: 'In6'!$C$79:$L$88
Name Matrix7: 'In7'!$C$79:$L$88
Name Matrix8: 'In8'!$C$79:$L$88
Name Matrix9: 'In9'!$C$79:$L$88
Name p_sel: Summary!$B$9
Name RGGM1: 'In1'!$N$91:$N$100
Name RGGM10: 'In10'!$N$91:$N$100
Name RGGM11: 'In11'!$N$91:$N$100
Name RGGM12: 'In12'!$N$91:$N$100
Name RGGM13: 'In13'!$N$91:$N$100
Name RGGM14: 'In14'!$N$91:$N$100
Name RGGM15: 'In15'!$N$91:$N$100
Name RGGM16: 'In16'!$N$91:$N$100
Name RGGM17: 'In17'!$N$91:$N$100
Name RGGM18: 'In18'!$N$91:$N$100
Name RGGM19: 'In19'!$N$91:$N$100
Name RGGM2: 'In2'!$N$91:$N$100
Name RGGM20: 'In20'!$N$91:$N$100
Name RGGM3: 'In3'!$N$91:$N$100

Sheet Summary
A1: AHP Analytic Hierarchy Process (EVM multiple inputs)
A2: K. D. Goepel Version 07.07.2022 | T2: 1 | U2: 2 | V2: 3 | W2: 4 | X2: 5 | Y2: 6 | Z2: 7 | AA2: 8
T3: AHP 1-9 | U3: Log | V3: Sqrt | W3: InvLin | X3: Bal-n | Y3: Power | Z3: Geom | AA3: Adaptive
A5: n= | B5: 3 | D5: Number of criteria (2 to 10) | J5: Scale: | K5: 1 | P5: =HLOOKUP(K5,T2:AA3,2) -> AHP 1-9
A7: N= | B7: 5 | D7: Number of Participants (1 to 20) | J7: a: | K7: 0.1 | N7: Consensus: | P7: =IF(B7>1,IF(OR(K5=1,K5=4,K5=5),(1/M63-1/A91)/(1-1/A91),"n/a"),"n/a") -> #VALUE!
B8: 3 | C8: 9
A9: p= | B9: 0 | D9: selected Participant (0=consol.) | J9: =2+MOD(B9,2)*11 -> 2 | K9: =7+(1+INT((B9-2)/2))*13 -> 7 | M9: =INDIRECT((ADDRESS(K9,J9,,,"multInp"))) -> Consolidated
A11: Objective | B11: Comparing Smoothness Factor Among Conventional Checkout, Self-Checkout and Unmanned Shop
A13: Author | B13: Group 2
A15: Date | G15: Thresh: | H15: 1e-08 | J15: Iterations: | K15: ='10x10'!M40 -> 9 | N15: EVM check: | O15: =check -> 2.592051e-09
A17: Table | B17: Criterion | F17: Comment | O17: Weights | P17: +/-
B18: 1 | C18: Conventional Cashier | O18: =O38 -> 0.36866814 | P18: =IF(B18>$B$5,0,_xlfn.STDEV.S(T50:AC50)) -> 0.032454463 | Q18: =IF(O18<>0,P18/O18,0) -> 0.088031645
B19: 2 | C19: Self-Checkout | O19: =O39 -> 0.22586548 | P19: =IF(B19>$B$5,0,_xlfn.STDEV.S(T51:AC51)) -> 0.019883309 | Q19: =IF(O19<>0,P19/O19,0) -> 0.088031645
B20: 3 | C20: Unmanned Shop | O20: =O40 -> 0.40546639 | P20: =IF(B20>$B$5,0,_xlfn.STDEV.S(T52:AC52)) -> 0.035693873 | Q20: =IF(O20<>0,P20/O20,0) -> 0.088031645
B21: 4 | O21: =O41 -> 2.8277089e-11 | P21: =IF(B21>$B$5,0,_xlfn.STDEV.S(T53:AC53)) -> 0 | Q21: =IF(O21<>0,P21/O21,0) -> 0
B22: 5 | O22: =O42 -> 2.8277089e-11 | P22: =IF(B22>$B$5,0,_xlfn.STDEV.S(T54:AC54)) -> 0 | Q22: =IF(O22<>0,P22/O22,0) -> 0
B23: 6 | O23: =O43 -> 2.8277089e-11 | P23: =IF(B23>$B$5,0,_xlfn.STDEV.S(T55:AC55)) -> 0 | Q23: =IF(O23<>0,P23/O23,0) -> 0
B24: 7 | O24: =O44 -> 2.8277089e-11 | P24: =IF(B24>$B$5,0,_xlfn.STDEV.S(T56:AC56)) -> 0 | Q24: =IF(O24<>0,P24/O24,0) -> 0
B25: 8 | O25: =O45 -> 2.8277089e-11 | P25: =IF(B25>$B$5,0,_xlfn.STDEV.S(T57:AC57)) -> 0 | Q25: =IF(O25<>0,P25/O25,0) -> 0
B26: 9 | F26: for 9&10 unprotect the input sheets and expand the | O26: =O46 -> 2.8277089e-11 | P26: =IF(B26>$B$5,0,_xlfn.STDEV.S(T58:AC58)) -> 0 | Q26: =IF(O26<>0,P26/O26,0) -> 0
B27: 10 | F27: question section ("+" in row 66) | O27: =O47 -> 2.8277089e-11 | P27: =IF(B27>$B$5,0,_xlfn.STDEV.S(T59:AC59)) -> 0 | Q27: =IF(O27<>0,P27/O27,0) -> 0
A30: Result | C30: Eigenvalue | K30: Lambda: | L30: ='10x10'!AG38 -> 3.0077696 | O30: MRE: | P30: =SQRT(SUMSQ(Q18:Q27)/B5) -> 0.088031645
C32: Consistency Ratio | G32: 0.37 | H32: GCI: | I32: =IF(B5>2,2*AC37/(B5-1)/(B5-2),"n/a") -> 0.023293847 | J32: Psi: | K32: =IF(B5>2,2/($B$5-1)/$B$5*SUM(T63:AC72),"n/a") -> 0.33333333 | L32: CR: | M32: =(L30-B5)/((2.7699*B5-4.3513)-B5) -> 0.0081068869 | O32: MRE est | P32: =SQRT(2*ROUND((L30-B5),5)/(B5-1)) -> 0.088147603
A36: Matrix | C36: {=TRANSPOSE(C18:C27)} -> Conventional Cashier | D36: Self-Checkout | E36: Unmanned Shop | F36: 0 | G36: 0 | H36: 0 | I36: 0 | J36: 0 | K36: 0 | L36: 0 | M36: normalized principal Eigenvector | T36: CGI Calculation
C37: 1 | D37: 2 | E37: 3 | F37: 4 | G37: 5 | H37: 6 | I37: 7 | J37: 8 | K37: 9 | L37: 10 | T37: 2 | U37: 3 | V37: 4 | W37: 5 | X37: 6 | Y37: 7 | Z37: 8 | AA37: 9 | AB37: 10 | AC37: =SUM(AC38:AC46) -> 0.023293847
A38: {=C18:C27} -> Conventional Cashier | B38: 1 | C38: 1 | D38: =IF(D50<>0,IF(D50>=1, CHOOSE( $K$5, D50, LOG(D50+1,2), SQRT(D50), 9/(10-D50), (9+($B$5-1)*D50)/(9+$B$5-D50), D50^2, 2^(D50-1),D50^(1+LN($B$5-1)/LN(9))), CHOOSE( $K$5, 1/D50, LOG(1/D50+1,2), SQRT(1/D50), 9/(10-1/D50), (9+($B$5-1)/D50)/(9+$B$5-1/D50), (1/D50)^2, 2^(1/D50-1),(1/D50)^(1+LN($B$5-1)/LN(9)))^-1),0) -> 1.7826025 | E38: =IF(E50<>0,IF(E50>=1, CHOOSE( $K$5, E50, LOG(E50+1,2), SQRT(E50), 9/(10-E50), (9+($B$5-1)*E50)/(9+$B$5-E50), E50^2, 2^(E50-1),E50^(1+LN($B$5-1)/LN(9))), CHOOSE( $K$5, 1/E50, LOG(1/E50+1,2), SQRT(1/E50), 9/(10-1/E50), (9+($B$5-1)/E50)/(9+$B$5-1/E50), (1/E50)^2, 2^(1/E50-1),(1/E50)^(1+LN($B$5-1)/LN(9)))^-1),0) -> 0.83255321 | F38: =IF(F50<>0,IF(F50>=1, CHOOSE( $K$5, F50, LOG(F50+1,2), SQRT(F50), 9/(10-F50), (9+($B$5-1)*F50)/(9+$B$5-F50), F50^2, 2^(F50-1),F50^(1+LN($B$5-1)/LN(9))), CHOOSE( $K$5, 1/F50, LOG(1/F50+1,2), SQRT(1/F50), 9/(10-1/F50), (9+($B$5-1)/F50)/(9+$B$5-1/F50), (1/F50)^2, 2^(1/F50-1),(1/F50)^(1+LN($B$5-1)/LN(9)))^-1),0) -> 0 | G38: =IF(G50<>0,IF(G50>=1, CHOOSE( $K$5, G50, LOG(G50+1,2), SQRT(G50), 9/(10-G50), (9+($B$5-1)*G50)/(9+$B$5-G50), G50^2, 2^(G50-1),G50^(1+LN($B$5-1)/LN(9))), CHOOSE( $K$5, 1/G50, LOG(1/G50+1,2), SQRT(1/G50), 9/(10-1/G50), (9+($B$5-1)/G50)/(9+$B$5-1/G50), (1/G50)^2, 2^(1/G50-1),(1/G50)^(1+LN($B$5-1)/LN(9)))^-1),0) -> 0 | H38: =IF(H50<>0,IF(H50>=1, CHOOSE( $K$5, H50, LOG(H50+1,2), SQRT(H50), 9/(10-H50), (9+($B$5-1)*H50)/(9+$B$5-H50), H50^2, 2^(H50-1),H50^(1+LN($B$5-1)/LN(9))), CHOOSE( $K$5, 1/H50, LOG(1/H50+1,2), SQRT(1/H50), 9/(10-1/H50), (9+($B$5-1)/H50)/(9+$B$5-1/H50), (1/H50)^2, 2^(1/H50-1),(1/H50)^(1+LN($B$5-1)/LN(9)))^-1),0) -> 0 | I38: =IF(I50<>0,IF(I50>=1, CHOOSE( $K$5, I50, LOG(I50+1,2), SQRT(I50), 9/(10-I50), (9+($B$5-1)*I50)/(9+$B$5-I50), I50^2, 2^(I50-1),I50^(1+LN($B$5-1)/LN(9))), CHOOSE( $K$5, 1/I50, LOG(1/I50+1,2), SQRT(1/I50), 9/(10-1/I50), (9+($B$5-1)/I50)/(9+$B$5-1/I50), (1/I50)^2, 2^(1/I50-1),(1/I50)^(1+LN($B$5-1)/LN(9)))^-1),0) -> 0 | J38: =IF(J50<>0,IF(J50>=1, CHOOSE( $K$5, J50, LOG(J50+1,2), SQRT(J50), 9/(10-J50), (9+($B$5-1)*J50)/(9+$B$5-J50), J50^2, 2^(J50-1),J50^(1+LN($B$5-1)/LN(9))), CHOOSE( $K$5, 1/J50, LOG(1/J50+1,2), SQRT(1/J50), 9/(10-1/J50), (9+($B$5-1)/J50)/(9+$B$5-1/J50), (1/J50)^2, 2^(1/J50-1),(1/J50)^(1+LN($B$5-1)/LN(9)))^-1),0) -> 0 | K38: =IF(K50<>0,IF(K50>=1, CHOOSE( $K$5, K50, LOG(K50+1,2), SQRT(K50), 9/(10-K50), (9+($B$5-1)*K50)/(9+$B$5-K50), K50^2, 2^(K50-1),K50^(1+LN($B$5-1)/LN(9))), CHOOSE( $K$5, 1/K50, LOG(1/K50+1,2), SQRT(1/K50), 9/(10-1/K50), (9+($B$5-1)/K50)/(9+$B$5-1/K50), (1/K50)^2, 2^(1/K50-1),(1/K50)^(1+LN($B$5-1)/LN(9)))^-1),0) -> 0 | L38: =IF(L50<>0,IF(L50>=1, CHOOSE( $K$5, L50, LOG(L50+1,2), SQRT(L50), 9/(10-L50), (9+($B$5-1)*L50)/(9+$B$5-L50), L50^2, 2^(L50-1),L50^(1+LN($B$5-1)/LN(9))), CHOOSE( $K$5, 1/L50, LOG(1/L50+1,2), SQRT(1/L50), 9/(10-1/L50), (9+($B$5-1)/L50)/(9+$B$5-1/L50), (1/L50)^2, 2^(1/L50-1),(1/L50)^(1+LN($B$5-1)/LN(9)))^-1),0) -> 0 | O38: {=EV_20} -> 0.36866814 | T38: =IF(OR($B38>$B$5,T$37>$B$5),0,(LN(OFFSET($B$37,$B38,T$37))-LN(OFFSET($O$37,$B38,0)/OFFSET($O$37,T$37,0)))^2) -> 0.0077646156 | U38: =IF(OR($B38>$B$5,U$37>$B$5),0,(LN(OFFSET($B$37,$B38,U$37))-LN(OFFSET($O$37,$B38,0)/OFFSET($O$37,U$37,0)))^2) -> 0.0077646156 | V38: =IF(OR($B38>$B$5,V$37>$B$5),0,(LN(OFFSET($B$37,$B38,V$37))-LN(OFFSET($O$37,$B38,0)/OFFSET($O$37,V$37,0)))^2) -> 0 | W38: =IF(OR($B38>$B$5,W$37>$B$5),0,(LN(OFFSET($B$37,$B38,W$37))-LN(OFFSET($O$37,$B38,0)/OFFSET($O$37,W$37,0)))^2) -> 0 | X38: =IF(OR($B38>$B$5,X$37>$B$5),0,(LN(OFFSET($B$37,$B38,X$37))-LN(OFFSET($O$37,$B38,0)/OFFSET($O$37,X$37,0)))^2) -> 0 | Y38: =IF(OR($B38>$B$5,Y$37>$B$5),0,(LN(OFFSET($B$37,$B38,Y$37))-LN(OFFSET($O$37,$B38,0)/OFFSET($O$37,Y$37,0)))^2) -> 0 | Z38: =IF(OR($B38>$B$5,Z$37>$B$5),0,(LN(OFFSET($B$37,$B38,Z$37))-LN(OFFSET($O$37,$B38,0)/OFFSET($O$37,Z$37,0)))^2) -> 0 | AA38: =IF(OR($B38>$B$5,AA$37>$B$5),0,(LN(OFFSET($B$37,$B38,AA$37))-LN(OFFSET($O$37,$B38,0)/OFFSET($O$37,AA$37,0)))^2) -> 0 | AB38: =IF(OR($B38>$B$5,AB$37>$B$5),0,(LN(OFFSET($B$37,$B38,AB$37))-LN(OFFSET($O$37,$B38,0)/OFFSET($O$37,AB$37,0)))^2) -> 0 | AC38: =SUM(T38:AB38) -> 0.015529231
A39: Self-Checkout | B39: 2 | C39: =IF(INDEX($C$38:$L$47,C$37,$B39)<>0,1/INDEX($C$38:$L$47,C$37,$B39),0) -> 0.56097757 | D39: 1 | E39: =IF(E51<>0,IF(E51>=1, CHOOSE( $K$5, E51, LOG(E51+1,2), SQRT(E51), 9/(10-E51), (9+($B$5-1)*E51)/(9+$B$5-E51), E51^2, 2^(E51-1),E51^(1+LN($B$5-1)/LN(9))), CHOOSE( $K$5, 1/E51, LOG(1/E51+1,2), SQRT(1/E51), 9/(10-1/E51), (9+($B$5-1)/E51)/(9+$B$5-1/E51), (1/E51)^2, 2^(1/E51-1),(1/E51)^(1+LN($B$5-1)/LN(9)))^-1),0) -> 0.60836434 | F39: =IF(F51<>0,IF(F51>=1, CHOOSE( $K$5, F51, LOG(F51+1,2), SQRT(F51), 9/(10-F51), (9+($B$5-1)*F51)/(9+$B$5-F51), F51^2, 2^(F51-1),F51^(1+LN($B$5-1)/LN(9))), CHOOSE( $K$5, 1/F51, LOG(1/F51+1,2), SQRT(1/F51), 9/(10-1/F51), (9+($B$5-1)/F51)/(9+$B$5-1/F51), (1/F51)^2, 2^(1/F51-1),(1/F51)^(1+LN($B$5-1)/LN(9)))^-1),0) -> 0 | G39: =IF(G51<>0,IF(G51>=1, CHOOSE( $K$5, G51, LOG(G51+1,2), SQRT(G51), 9/(10-G51), (9+($B$5-1)*G51)/(9+$B$5-G51), G51^2, 2^(G51-1),G51^(1+LN($B$5-1)/LN(9))), CHOOSE( $K$5, 1/G51, LOG(1/G51+1,2), SQRT(1/G51), 9/(10-1/G51), (9+($B$5-1)/G51)/(9+$B$5-1/G51), (1/G51)^2, 2^(1/G51-1),(1/G51)^(1+LN($B$5-1)/LN(9)))^-1),0) -> 0 | H39: =IF(H51<>0,IF(H51>=1, CHOOSE( $K$5, H51, LOG(H51+1,2), SQRT(H51), 9/(10-H51), (9+($B$5-1)*H51)/(9+$B$5-H51), H51^2, 2^(H51-1),H51^(1+LN($B$5-1)/LN(9))), CHOOSE( $K$5, 1/H51, LOG(1/H51+1,2), SQRT(1/H51), 9/(10-1/H51), (9+($B$5-1)/H51)/(9+$B$5-1/H51), (1/H51)^2, 2^(1/H51-1),(1/H51)^(1+LN($B$5-1)/LN(9)))^-1),0) -> 0 | I39: =IF(I51<>0,IF(I51>=1, CHOOSE( $K$5, I51, LOG(I51+1,2), SQRT(I51), 9/(10-I51), (9+($B$5-1)*I51)/(9+$B$5-I51), I51^2, 2^(I51-1),I51^(1+LN($B$5-1)/LN(9))), CHOOSE( $K$5, 1/I51, LOG(1/I51+1,2), SQRT(1/I51), 9/(10-1/I51), (9+($B$5-1)/I51)/(9+$B$5-1/I51), (1/I51)^2, 2^(1/I51-1),(1/I51)^(1+LN($B$5-1)/LN(9)))^-1),0) -> 0 | J39: =IF(J51<>0,IF(J51>=1, CHOOSE( $K$5, J51, LOG(J51+1,2), SQRT(J51), 9/(10-J51), (9+($B$5-1)*J51)/(9+$B$5-J51), J51^2, 2^(J51-1),J51^(1+LN($B$5-1)/LN(9))), CHOOSE( $K$5, 1/J51, LOG(1/J51+1,2), SQRT(1/J51), 9/(10-1/J51), (9+($B$5-1)/J51)/(9+$B$5-1/J51), (1/J51)^2, 2^(1/J51-1),(1/J51)^(1+LN($B$5-1)/LN(9)))^-1),0) -> 0 | K39: =IF(K51<>0,IF(K51>=1, CHOOSE( $K$5, K51, LOG(K51+1,2), SQRT(K51), 9/(10-K51), (9+($B$5-1)*K51)/(9+$B$5-K51), K51^2, 2^(K51-1),K51^(1+LN($B$5-1)/LN(9))), CHOOSE( $K$5, 1/K51, LOG(1/K51+1,2), SQRT(1/K51), 9/(10-1/K51), (9+($B$5-1)/K51)/(9+$B$5-1/K51), (1/K51)^2, 2^(1/K51-1),(1/K51)^(1+LN($B$5-1)/LN(9)))^-1),0) -> 0 | L39: =IF(L51<>0,IF(L51>=1, CHOOSE( $K$5, L51, LOG(L51+1,2), SQRT(L51), 9/(10-L51), (9+($B$5-1)*L51)/(9+$B$5-L51), L51^2, 2^(L51-1),L51^(1+LN($B$5-1)/LN(9))), CHOOSE( $K$5, 1/L51, LOG(1/L51+1,2), SQRT(1/L51), 9/(10-1/L51), (9+($B$5-1)/L51)/(9+$B$5-1/L51), (1/L51)^2, 2^(1/L51-1),(1/L51)^(1+LN($B$5-1)/LN(9)))^-1),0) -> 0 | O39: 0.22586548 | U39: =IF(OR($B39>$B$5,U$37>$B$5),0,(LN(OFFSET($B$37,$B39,U$37))-LN(OFFSET($O$37,$B39,0)/OFFSET($O$37,U$37,0)))^2) -> 0.0077646156 | V39: =IF(OR($B39>$B$5,V$37>$B$5),0,(LN(OFFSET($B$37,$B39,V$37))-LN(OFFSET($O$37,$B39,0)/OFFSET($O$37,V$37,0)))^2) -> 0 | W39: =IF(OR($B39>$B$5,W$37>$B$5),0,(LN(OFFSET($B$37,$B39,W$37))-LN(OFFSET($O$37,$B39,0)/OFFSET($O$37,W$37,0)))^2) -> 0 | X39: =IF(OR($B39>$B$5,X$37>$B$5),0,(LN(OFFSET($B$37,$B39,X$37))-LN(OFFSET($O$37,$B39,0)/OFFSET($O$37,X$37,0)))^2) -> 0 | Y39: =IF(OR($B39>$B$5,Y$37>$B$5),0,(LN(OFFSET($B$37,$B39,Y$37))-LN(OFFSET($O$37,$B39,0)/OFFSET($O$37,Y$37,0)))^2) -> 0 | Z39: =IF(OR($B39>$B$5,Z$37>$B$5),0,(LN(OFFSET($B$37,$B39,Z$37))-LN(OFFSET($O$37,$B39,0)/OFFSET($O$37,Z$37,0)))^2) -> 0 | AA39: =IF(OR($B39>$B$5,AA$37>$B$5),0,(LN(OFFSET($B$37,$B39,AA$37))-LN(OFFSET($O$37,$B39,0)/OFFSET($O$37,AA$37,0)))^2) -> 0 | AB39: =IF(OR($B39>$B$5,AB$37>$B$5),0,(LN(OFFSET($B$37,$B39,AB$37))-LN(OFFSET($O$37,$B39,0)/OFFSET($O$37,AB$37,0)))^2) -> 0 | AC39: =SUM(T39:AB39) -> 0.0077646156
A40: Unmanned Shop | B40: 3 | C40: =IF(INDEX($C$38:$L$47,C$37,$B40)<>0,1/INDEX($C$38:$L$47,C$37,$B40),0) -> 1.2011244 | D40: =IF(INDEX($C$38:$L$47,D$37,$B40)<>0,1/INDEX($C$38:$L$47,D$37,$B40),0) -> 1.6437518 | E40: 1 | F40: =IF(F52<>0,IF(F52>=1, CHOOSE( $K$5, F52, LOG(F52+1,2), SQRT(F52), 9/(10-F52), (9+($B$5-1)*F52)/(9+$B$5-F52), F52^2, 2^(F52-1),F52^(1+LN($B$5-1)/LN(9))), CHOOSE( $K$5, 1/F52, LOG(1/F52+1,2), SQRT(1/F52), 9/(10-1/F52), (9+($B$5-1)/F52)/(9+$B$5-1/F52), (1/F52)^2, 2^(1/F52-1),(1/F52)^(1+LN($B$5-1)/LN(9)))^-1),0) -> 0 | G40: =IF(G52<>0,IF(G52>=1, CHOOSE( $K$5, G52, LOG(G52+1,2), SQRT(G52), 9/(10-G52), (9+($B$5-1)*G52)/(9+$B$5-G52), G52^2, 2^(G52-1),G52^(1+LN($B$5-1)/LN(9))), CHOOSE( $K$5, 1/G52, LOG(1/G52+1,2), SQRT(1/G52), 9/(10-1/G52), (9+($B$5-1)/G52)/(9+$B$5-1/G52), (1/G52)^2, 2^(1/G52-1),(1/G52)^(1+LN($B$5-1)/LN(9)))^-1),0) -> 0 | H40: =IF(H52<>0,IF(H52>=1, CHOOSE( $K$5, H52, LOG(H52+1,2), SQRT(H52), 9/(10-H52), (9+($B$5-1)*H52)/(9+$B$5-H52), H52^2, 2^(H52-1),H52^(1+LN($B$5-1)/LN(9))), CHOOSE( $K$5, 1/H52, LOG(1/H52+1,2), SQRT(1/H52), 9/(10-1/H52), (9+($B$5-1)/H52)/(9+$B$5-1/H52), (1/H52)^2, 2^(1/H52-1),(1/H52)^(1+LN($B$5-1)/LN(9)))^-1),0) -> 0 | I40: =IF(I52<>0,IF(I52>=1, CHOOSE( $K$5, I52, LOG(I52+1,2), SQRT(I52), 9/(10-I52), (9+($B$5-1)*I52)/(9+$B$5-I52), I52^2, 2^(I52-1),I52^(1+LN($B$5-1)/LN(9))), CHOOSE( $K$5, 1/I52, LOG(1/I52+1,2), SQRT(1/I52), 9/(10-1/I52), (9+($B$5-1)/I52)/(9+$B$5-1/I52), (1/I52)^2, 2^(1/I52-1),(1/I52)^(1+LN($B$5-1)/LN(9)))^-1),0) -> 0 | J40: =IF(J52<>0,IF(J52>=1, CHOOSE( $K$5, J52, LOG(J52+1,2), SQRT(J52), 9/(10-J52), (9+($B$5-1)*J52)/(9+$B$5-J52), J52^2, 2^(J52-1),J52^(1+LN($B$5-1)/LN(9))), CHOOSE( $K$5, 1/J52, LOG(1/J52+1,2), SQRT(1/J52), 9/(10-1/J52), (9+($B$5-1)/J52)/(9+$B$5-1/J52), (1/J52)^2, 2^(1/J52-1),(1/J52)^(1+LN($B$5-1)/LN(9)))^-1),0) -> 0 | K40: =IF(K52<>0,IF(K52>=1, CHOOSE( $K$5, K52, LOG(K52+1,2), SQRT(K52), 9/(10-K52), (9+($B$5-1)*K52)/(9+$B$5-K52), K52^2, 2^(K52-1),K52^(1+LN($B$5-1)/LN(9))), CHOOSE( $K$5, 1/K52, LOG(1/K52+1,2), SQRT(1/K52), 9/(10-1/K52), (9+($B$5-1)/K52)/(9+$B$5-1/K52), (1/K52)^2, 2^(1/K52-1),(1/K52)^(1+LN($B$5-1)/LN(9)))^-1),0) -> 0 | L40: =IF(L52<>0,IF(L52>=1, CHOOSE( $K$5, L52, LOG(L52+1,2), SQRT(L52), 9/(10-L52), (9+($B$5-1)*L52)/(9+$B$5-L52), L52^2, 2^(L52-1),L52^(1+LN($B$5-1)/LN(9))), CHOOSE( $K$5, 1/L52, LOG(1/L52+1,2), SQRT(1/L52), 9/(10-1/L52), (9+($B$5-1)/L52)/(9+$B$5-1/L52), (1/L52)^2, 2^(1/L52-1),(1/L52)^(1+LN($B$5-1)/LN(9)))^-1),0) -> 0 | O40: 0.40546639 | V40: =IF(OR($B40>$B$5,V$37>$B$5),0,(LN(OFFSET($B$37,$B40,V$37))-LN(OFFSET($O$37,$B40,0)/OFFSET($O$37,V$37,0)))^2) -> 0 | W40: =IF(OR($B40>$B$5,W$37>$B$5),0,(LN(OFFSET($B$37,$B40,W$37))-LN(OFFSET($O$37,$B40,0)/OFFSET($O$37,W$37,0)))^2) -> 0 | X40: =IF(OR($B40>$B$5,X$37>$B$5),0,(LN(OFFSET($B$37,$B40,X$37))-LN(OFFSET($O$37,$B40,0)/OFFSET($O$37,X$37,0)))^2) -> 0 | Y40: =IF(OR($B40>$B$5,Y$37>$B$5),0,(LN(OFFSET($B$37,$B40,Y$37))-LN(OFFSET($O$37,$B40,0)/OFFSET($O$37,Y$37,0)))^2) -> 0 | Z40: =IF(OR($B40>$B$5,Z$37>$B$5),0,(LN(OFFSET($B$37,$B40,Z$37))-LN(OFFSET($O$37,$B40,0)/OFFSET($O$37,Z$37,0)))^2) -> 0 | AA40: =IF(OR($B40>$B$5,AA$37>$B$5),0,(LN(OFFSET($B$37,$B40,AA$37))-LN(OFFSET($O$37,$B40,0)/OFFSET($O$37,AA$37,0)))^2) -> 0 | AB40: =IF(OR($B40>$B$5,AB$37>$B$5),0,(LN(OFFSET($B$37,$B40,AB$37))-LN(OFFSET($O$37,$B40,0)/OFFSET($O$37,AB$37,0)))^2) -> 0 | AC40: =SUM(T40:AB40) -> 0
A41: 0 | B41: 4 | C41: =IF(INDEX($C$38:$L$47,C$37,$B41)<>0,1/INDEX($C$38:$L$47,C$37,$B41),0) -> 0 | D41: =IF(INDEX($C$38:$L$47,D$37,$B41)<>0,1/INDEX($C$38:$L$47,D$37,$B41),0) -> 0 | E41: =IF(INDEX($C$38:$L$47,E$37,$B41)<>0,1/INDEX($C$38:$L$47,E$37,$B41),0) -> 0 | F41: 1 | G41: =IF(G53<>0,IF(G53>=1, CHOOSE( $K$5, G53, LOG(G53+1,2), SQRT(G53), 9/(10-G53), (9+($B$5-1)*G53)/(9+$B$5-G53), G53^2, 2^(G53-1),G53^(1+LN($B$5-1)/LN(9))), CHOOSE( $K$5, 1/G53, LOG(1/G53+1,2), SQRT(1/G53), 9/(10-1/G53), (9+($B$5-1)/G53)/(9+$B$5-1/G53), (1/G53)^2, 2^(1/G53-1),(1/G53)^(1+LN($B$5-1)/LN(9)))^-1),0) -> 0 | H41: =IF(H53<>0,IF(H53>=1, CHOOSE( $K$5, H53, LOG(H53+1,2), SQRT(H53), 9/(10-H53), (9+($B$5-1)*H53)/(9+$B$5-H53), H53^2, 2^(H53-1),H53^(1+LN($B$5-1)/LN(9))), CHOOSE( $K$5, 1/H53, LOG(1/H53+1,2), SQRT(1/H53), 9/(10-1/H53), (9+($B$5-1)/H53)/(9+$B$5-1/H53), (1/H53)^2, 2^(1/H53-1),(1/H53)^(1+LN($B$5-1)/LN(9)))^-1),0) -> 0 | I41: =IF(I53<>0,IF(I53>=1, CHOOSE( $K$5, I53, LOG(I53+1,2), SQRT(I53), 9/(10-I53), (9+($B$5-1)*I53)/(9+$B$5-I53), I53^2, 2^(I53-1),I53^(1+LN($B$5-1)/LN(9))), CHOOSE( $K$5, 1/I53, LOG(1/I53+1,2), SQRT(1/I53), 9/(10-1/I53), (9+($B$5-1)/I53)/(9+$B$5-1/I53), (1/I53)^2, 2^(1/I53-1),(1/I53)^(1+LN($B$5-1)/LN(9)))^-1),0) -> 0 | J41: =IF(J53<>0,IF(J53>=1, CHOOSE( $K$5, J53, LOG(J53+1,2), SQRT(J53), 9/(10-J53), (9+($B$5-1)*J53)/(9+$B$5-J53), J53^2, 2^(J53-1),J53^(1+LN($B$5-1)/LN(9))), CHOOSE( $K$5, 1/J53, LOG(1/J53+1,2), SQRT(1/J53), 9/(10-1/J53), (9+($B$5-1)/J53)/(9+$B$5-1/J53), (1/J53)^2, 2^(1/J53-1),(1/J53)^(1+LN($B$5-1)/LN(9)))^-1),0) -> 0 | K41: =IF(K53<>0,IF(K53>=1, CHOOSE( $K$5, K53, LOG(K53+1,2), SQRT(K53), 9/(10-K53), (9+($B$5-1)*K53)/(9+$B$5-K53), K53^2, 2^(K53-1),K53^(1+LN($B$5-1)/LN(9))), CHOOSE( $K$5, 1/K53, LOG(1/K53+1,2), SQRT(1/K53), 9/(10-1/K53), (9+($B$5-1)/K53)/(9+$B$5-1/K53), (1/K53)^2, 2^(1/K53-1),(1/K53)^(1+LN($B$5-1)/LN(9)))^-1),0) -> 0 | L41: =IF(L53<>0,IF(L53>=1, CHOOSE( $K$5, L53, LOG(L53+1,2), SQRT(L53), 9/(10-L53), (9+($B$5-1)*L53)/(9+$B$5-L53), L53^2, 2^(L53-1),L53^(1+LN($B$5-1)/LN(9))), CHOOSE( $K$5, 1/L53, LOG(1/L53+1,2), SQRT(1/L53), 9/(10-1/L53), (9+($B$5-1)/L53)/(9+$B$5-1/L53), (1/L53)^2, 2^(1/L53-1),(1/L53)^(1+LN($B$5-1)/LN(9)))^-1),0) -> 0 | O41: 2.8277089e-11 | W41: =IF(OR($B41>$B$5,W$37>$B$5),0,(LN(OFFSET($B$37,$B41,W$37))-LN(OFFSET($O$37,$B41,0)/OFFSET($O$37,W$37,0)))^2) -> 0 | X41: =IF(OR($B41>$B$5,X$37>$B$5),0,(LN(OFFSET($B$37,$B41,X$37))-LN(OFFSET($O$37,$B41,0)/OFFSET($O$37,X$37,0)))^2) -> 0 | Y41: =IF(OR($B41>$B$5,Y$37>$B$5),0,(LN(OFFSET($B$37,$B41,Y$37))-LN(OFFSET($O$37,$B41,0)/OFFSET($O$37,Y$37,0)))^2) -> 0 | Z41: =IF(OR($B41>$B$5,Z$37>$B$5),0,(LN(OFFSET($B$37,$B41,Z$37))-LN(OFFSET($O$37,$B41,0)/OFFSET($O$37,Z$37,0)))^2) -> 0 | AA41: =IF(OR($B41>$B$5,AA$37>$B$5),0,(LN(OFFSET($B$37,$B41,AA$37))-LN(OFFSET($O$37,$B41,0)/OFFSET($O$37,AA$37,0)))^2) -> 0 | AB41: =IF(OR($B41>$B$5,AB$37>$B$5),0,(LN(OFFSET($B$37,$B41,AB$37))-LN(OFFSET($O$37,$B41,0)/OFFSET($O$37,AB$37,0)))^2) -> 0 | AC41: =SUM(T41:AB41) -> 0
A42: 0 | B42: 5 | C42: =IF(INDEX($C$38:$L$47,C$37,$B42)<>0,1/INDEX($C$38:$L$47,C$37,$B42),0) -> 0 | D42: =IF(INDEX($C$38:$L$47,D$37,$B42)<>0,1/INDEX($C$38:$L$47,D$37,$B42),0) -> 0 | E42: =IF(INDEX($C$38:$L$47,E$37,$B42)<>0,1/INDEX($C$38:$L$47,E$37,$B42),0) -> 0 | F42: =IF(INDEX($C$38:$L$47,F$37,$B42)<>0,1/INDEX($C$38:$L$47,F$37,$B42),0) -> 0 | G42: 1 | H42: =IF(H54<>0,IF(H54>=1, CHOOSE( $K$5, H54, LOG(H54+1,2), SQRT(H54), 9/(10-H54), (9+($B$5-1)*H54)/(9+$B$5-H54), H54^2, 2^(H54-1),H54^(1+LN($B$5-1)/LN(9))), CHOOSE( $K$5, 1/H54, LOG(1/H54+1,2), SQRT(1/H54), 9/(10-1/H54), (9+($B$5-1)/H54)/(9+$B$5-1/H54), (1/H54)^2, 2^(1/H54-1),(1/H54)^(1+LN($B$5-1)/LN(9)))^-1),0) -> 0 | I42: =IF(I54<>0,IF(I54>=1, CHOOSE( $K$5, I54, LOG(I54+1,2), SQRT(I54), 9/(10-I54), (9+($B$5-1)*I54)/(9+$B$5-I54), I54^2, 2^(I54-1),I54^(1+LN($B$5-1)/LN(9))), CHOOSE( $K$5, 1/I54, LOG(1/I54+1,2), SQRT(1/I54), 9/(10-1/I54), (9+($B$5-1)/I54)/(9+$B$5-1/I54), (1/I54)^2, 2^(1/I54-1),(1/I54)^(1+LN($B$5-1)/LN(9)))^-1),0) -> 0 | J42: =IF(J54<>0,IF(J54>=1, CHOOSE( $K$5, J54, LOG(J54+1,2), SQRT(J54), 9/(10-J54), (9+($B$5-1)*J54)/(9+$B$5-J54), J54^2, 2^(J54-1),J54^(1+LN($B$5-1)/LN(9))), CHOOSE( $K$5, 1/J54, LOG(1/J54+1,2), SQRT(1/J54), 9/(10-1/J54), (9+($B$5-1)/J54)/(9+$B$5-1/J54), (1/J54)^2, 2^(1/J54-1),(1/J54)^(1+LN($B$5-1)/LN(9)))^-1),0) -> 0 | K42: =IF(K54<>0,IF(K54>=1, CHOOSE( $K$5, K54, LOG(K54+1,2), SQRT(K54), 9/(10-K54), (9+($B$5-1)*K54)/(9+$B$5-K54), K54^2, 2^(K54-1),K54^(1+LN($B$5-1)/LN(9))), CHOOSE( $K$5, 1/K54, LOG(1/K54+1,2), SQRT(1/K54), 9/(10-1/K54), (9+($B$5-1)/K54)/(9+$B$5-1/K54), (1/K54)^2, 2^(1/K54-1),(1/K54)^(1+LN($B$5-1)/LN(9)))^-1),0) -> 0 | L42: =IF(L54<>0,IF(L54>=1, CHOOSE( $K$5, L54, LOG(L54+1,2), SQRT(L54), 9/(10-L54), (9+($B$5-1)*L54)/(9+$B$5-L54), L54^2, 2^(L54-1),L54^(1+LN($B$5-1)/LN(9))), CHOOSE( $K$5, 1/L54, LOG(1/L54+1,2), SQRT(1/L54), 9/(10-1/L54), (9+($B$5-1)/L54)/(9+$B$5-1/L54), (1/L54)^2, 2^(1/L54-1),(1/L54)^(1+LN($B$5-1)/LN(9)))^-1),0) -> 0 | O42: 2.8277089e-11 | X42: =IF(OR($B42>$B$5,X$37>$B$5),0,(LN(OFFSET($B$37,$B42,X$37))-LN(OFFSET($O$37,$B42,0)/OFFSET($O$37,X$37,0)))^2) -> 0 | Y42: =IF(OR($B42>$B$5,Y$37>$B$5),0,(LN(OFFSET($B$37,$B42,Y$37))-LN(OFFSET($O$37,$B42,0)/OFFSET($O$37,Y$37,0)))^2) -> 0 | Z42: =IF(OR($B42>$B$5,Z$37>$B$5),0,(LN(OFFSET($B$37,$B42,Z$37))-LN(OFFSET($O$37,$B42,0)/OFFSET($O$37,Z$37,0)))^2) -> 0 | AA42: =IF(OR($B42>$B$5,AA$37>$B$5),0,(LN(OFFSET($B$37,$B42,AA$37))-LN(OFFSET($O$37,$B42,0)/OFFSET($O$37,AA$37,0)))^2) -> 0 | AB42: =IF(OR($B42>$B$5,AB$37>$B$5),0,(LN(OFFSET($B$37,$B42,AB$37))-LN(OFFSET($O$37,$B42,0)/OFFSET($O$37,AB$37,0)))^2) -> 0 | AC42: =SUM(T42:AB42) -> 0
A43: 0 | B43: 6 | C43: =IF(INDEX($C$38:$L$47,C$37,$B43)<>0,1/INDEX($C$38:$L$47,C$37,$B43),0) -> 0 | D43: =IF(INDEX($C$38:$L$47,D$37,$B43)<>0,1/INDEX($C$38:$L$47,D$37,$B43),0) -> 0 | E43: =IF(INDEX($C$38:$L$47,E$37,$B43)<>0,1/INDEX($C$38:$L$47,E$37,$B43),0) -> 0 | F43: =IF(INDEX($C$38:$L$47,F$37,$B43)<>0,1/INDEX($C$38:$L$47,F$37,$B43),0) -> 0 | G43: =IF(INDEX($C$38:$L$47,G$37,$B43)<>0,1/INDEX($C$38:$L$47,G$37,$B43),0) -> 0 | H43: 1 | I43: =IF(I55<>0,IF(I55>=1, CHOOSE( $K$5, I55, LOG(I55+1,2), SQRT(I55), 9/(10-I55), (9+($B$5-1)*I55)/(9+$B$5-I55), I55^2, 2^(I55-1),I55^(1+LN($B$5-1)/LN(9))), CHOOSE( $K$5, 1/I55, LOG(1/I55+1,2), SQRT(1/I55), 9/(10-1/I55), (9+($B$5-1)/I55)/(9+$B$5-1/I55), (1/I55)^2, 2^(1/I55-1),(1/I55)^(1+LN($B$5-1)/LN(9)))^-1),0) -> 0 | J43: =IF(J55<>0,IF(J55>=1, CHOOSE( $K$5, J55, LOG(J55+1,2), SQRT(J55), 9/(10-J55), (9+($B$5-1)*J55)/(9+$B$5-J55), J55^2, 2^(J55-1),J55^(1+LN($B$5-1)/LN(9))), CHOOSE( $K$5, 1/J55, LOG(1/J55+1,2), SQRT(1/J55), 9/(10-1/J55), (9+($B$5-1)/J55)/(9+$B$5-1/J55), (1/J55)^2, 2^(1/J55-1),(1/J55)^(1+LN($B$5-1)/LN(9)))^-1),0) -> 0 | K43: =IF(K55<>0,IF(K55>=1, CHOOSE( $K$5, K55, LOG(K55+1,2), SQRT(K55), 9/(10-K55), (9+($B$5-1)*K55)/(9+$B$5-K55), K55^2, 2^(K55-1),K55^(1+LN($B$5-1)/LN(9))), CHOOSE( $K$5, 1/K55, LOG(1/K55+1,2), SQRT(1/K55), 9/(10-1/K55), (9+($B$5-1)/K55)/(9+$B$5-1/K55), (1/K55)^2, 2^(1/K55-1),(1/K55)^(1+LN($B$5-1)/LN(9)))^-1),0) -> 0 | L43: =IF(L55<>0,IF(L55>=1, CHOOSE( $K$5, L55, LOG(L55+1,2), SQRT(L55), 9/(10-L55), (9+($B$5-1)*L55)/(9+$B$5-L55), L55^2, 2^(L55-1),L55^(1+LN($B$5-1)/LN(9))), CHOOSE( $K$5, 1/L55, LOG(1/L55+1,2), SQRT(1/L55), 9/(10-1/L55), (9+($B$5-1)/L55)/(9+$B$5-1/L55), (1/L55)^2, 2^(1/L55-1),(1/L55)^(1+LN($B$5-1)/LN(9)))^-1),0) -> 0 | O43: 2.8277089e-11 | Y43: =IF(OR($B43>$B$5,Y$37>$B$5),0,(LN(OFFSET($B$37,$B43,Y$37))-LN(OFFSET($O$37,$B43,0)/OFFSET($O$37,Y$37,0)))^2) -> 0 | Z43: =IF(OR($B43>$B$5,Z$37>$B$5),0,(LN(OFFSET($B$37,$B43,Z$37))-LN(OFFSET($O$37,$B43,0)/OFFSET($O$37,Z$37,0)))^2) -> 0 | AA43: =IF(OR($B43>$B$5,AA$37>$B$5),0,(LN(OFFSET($B$37,$B43,AA$37))-LN(OFFSET($O$37,$B43,0)/OFFSET($O$37,AA$37,0)))^2) -> 0 | AB43: =IF(OR($B43>$B$5,AB$37>$B$5),0,(LN(OFFSET($B$37,$B43,AB$37))-LN(OFFSET($O$37,$B43,0)/OFFSET($O$37,AB$37,0)))^2) -> 0 | AC43: =SUM(T43:AB43) -> 0
A44: 0 | B44: 7 | C44: =IF(INDEX($C$38:$L$47,C$37,$B44)<>0,1/INDEX($C$38:$L$47,C$37,$B44),0) -> 0 | D44: =IF(INDEX($C$38:$L$47,D$37,$B44)<>0,1/INDEX($C$38:$L$47,D$37,$B44),0) -> 0 | E44: =IF(INDEX($C$38:$L$47,E$37,$B44)<>0,1/INDEX($C$38:$L$47,E$37,$B44),0) -> 0 | F44: =IF(INDEX($C$38:$L$47,F$37,$B44)<>0,1/INDEX($C$38:$L$47,F$37,$B44),0) -> 0 | G44: =IF(INDEX($C$38:$L$47,G$37,$B44)<>0,1/INDEX($C$38:$L$47,G$37,$B44),0) -> 0 | H44: =IF(INDEX($C$38:$L$47,H$37,$B44)<>0,1/INDEX($C$38:$L$47,H$37,$B44),0) -> 0 | I44: 1 | J44: =IF(J56<>0,IF(J56>=1, CHOOSE( $K$5, J56, LOG(J56+1,2), SQRT(J56), 9/(10-J56), (9+($B$5-1)*J56)/(9+$B$5-J56), J56^2, 2^(J56-1),J56^(1+LN($B$5-1)/LN(9))), CHOOSE( $K$5, 1/J56, LOG(1/J56+1,2), SQRT(1/J56), 9/(10-1/J56), (9+($B$5-1)/J56)/(9+$B$5-1/J56), (1/J56)^2, 2^(1/J56-1),(1/J56)^(1+LN($B$5-1)/LN(9)))^-1),0) -> 0 | K44: =IF(K56<>0,IF(K56>=1, CHOOSE( $K$5, K56, LOG(K56+1,2), SQRT(K56), 9/(10-K56), (9+($B$5-1)*K56)/(9+$B$5-K56), K56^2, 2^(K56-1),K56^(1+LN($B$5-1)/LN(9))), CHOOSE( $K$5, 1/K56, LOG(1/K56+1,2), SQRT(1/K56), 9/(10-1/K56), (9+($B$5-1)/K56)/(9+$B$5-1/K56), (1/K56)^2, 2^(1/K56-1),(1/K56)^(1+LN($B$5-1)/LN(9)))^-1),0) -> 0 | L44: =IF(L56<>0,IF(L56>=1, CHOOSE( $K$5, L56, LOG(L56+1,2), SQRT(L56), 9/(10-L56), (9+($B$5-1)*L56)/(9+$B$5-L56), L56^2, 2^(L56-1),L56^(1+LN($B$5-1)/LN(9))), CHOOSE( $K$5, 1/L56, LOG(1/L56+1,2), SQRT(1/L56), 9/(10-1/L56), (9+($B$5-1)/L56)/(9+$B$5-1/L56), (1/L56)^2, 2^(1/L56-1),(1/L56)^(1+LN($B$5-1)/LN(9)))^-1),0) -> 0 | O44: 2.8277089e-11 | Z44: =IF(OR($B44>$B$5,Z$37>$B$5),0,(LN(OFFSET($B$37,$B44,Z$37))-LN(OFFSET($O$37,$B44,0)/OFFSET($O$37,Z$37,0)))^2) -> 0 | AA44: =IF(OR($B44>$B$5,AA$37>$B$5),0,(LN(OFFSET($B$37,$B44,AA$37))-LN(OFFSET($O$37,$B44,0)/OFFSET($O$37,AA$37,0)))^2) -> 0 | AB44: =IF(OR($B44>$B$5,AB$37>$B$5),0,(LN(OFFSET($B$37,$B44,AB$37))-LN(OFFSET($O$37,$B44,0)/OFFSET($O$37,AB$37,0)))^2) -> 0 | AC44: =SUM(T44:AB44) -> 0
A45: 0 | B45: 8 | C45: =IF(INDEX($C$38:$L$47,C$37,$B45)<>0,1/INDEX($C$38:$L$47,C$37,$B45),0) -> 0 | D45: =IF(INDEX($C$38:$L$47,D$37,$B45)<>0,1/INDEX($C$38:$L$47,D$37,$B45),0) -> 0 | E45: =IF(INDEX($C$38:$L$47,E$37,$B45)<>0,1/INDEX($C$38:$L$47,E$37,$B45),0) -> 0 | F45: =IF(INDEX($C$38:$L$47,F$37,$B45)<>0,1/INDEX($C$38:$L$47,F$37,$B45),0) -> 0 | G45: =IF(INDEX($C$38:$L$47,G$37,$B45)<>0,1/INDEX($C$38:$L$47,G$37,$B45),0) -> 0 | H45: =IF(INDEX($C$38:$L$47,H$37,$B45)<>0,1/INDEX($C$38:$L$47,H$37,$B45),0) -> 0 | I45: =IF(INDEX($C$38:$L$47,I$37,$B45)<>0,1/INDEX($C$38:$L$47,I$37,$B45),0) -> 0 | J45: 1 | K45: =IF(K57<>0,IF(K57>=1, CHOOSE( $K$5, K57, LOG(K57+1,2), SQRT(K57), 9/(10-K57), (9+($B$5-1)*K57)/(9+$B$5-K57), K57^2, 2^(K57-1),K57^(1+LN($B$5-1)/LN(9))), CHOOSE( $K$5, 1/K57, LOG(1/K57+1,2), SQRT(1/K57), 9/(10-1/K57), (9+($B$5-1)/K57)/(9+$B$5-1/K57), (1/K57)^2, 2^(1/K57-1),(1/K57)^(1+LN($B$5-1)/LN(9)))^-1),0) -> 0 | L45: =IF(L57<>0,IF(L57>=1, CHOOSE( $K$5, L57, LOG(L57+1,2), SQRT(L57), 9/(10-L57), (9+($B$5-1)*L57)/(9+$B$5-L57), L57^2, 2^(L57-1),L57^(1+LN($B$5-1)/LN(9))), CHOOSE( $K$5, 1/L57, LOG(1/L57+1,2), SQRT(1/L57), 9/(10-1/L57), (9+($B$5-1)/L57)/(9+$B$5-1/L57), (1/L57)^2, 2^(1/L57-1),(1/L57)^(1+LN($B$5-1)/LN(9)))^-1),0) -> 0 | O45: 2.8277089e-11 | AA45: =IF(OR($B45>$B$5,AA$37>$B$5),0,(LN(OFFSET($B$37,$B45,AA$37))-LN(OFFSET($O$37,$B45,0)/OFFSET($O$37,AA$37,0)))^2) -> 0 | AB45: =IF(OR($B45>$B$5,AB$37>$B$5),0,(LN(OFFSET($B$37,$B45,AB$37))-LN(OFFSET($O$37,$B45,0)/OFFSET($O$37,AB$37,0)))^2) -> 0 | AC45: =SUM(T45:AB45) -> 0
A46: 0 | B46: 9 | C46: =IF(INDEX($C$38:$L$47,C$37,$B46)<>0,1/INDEX($C$38:$L$47,C$37,$B46),0) -> 0 | D46: =IF(INDEX($C$38:$L$47,D$37,$B46)<>0,1/INDEX($C$38:$L$47,D$37,$B46),0) -> 0 | E46: =IF(INDEX($C$38:$L$47,E$37,$B46)<>0,1/INDEX($C$38:$L$47,E$37,$B46),0) -> 0 | F46: =IF(INDEX($C$38:$L$47,F$37,$B46)<>0,1/INDEX($C$38:$L$47,F$37,$B46),0) -> 0 | G46: =IF(INDEX($C$38:$L$47,G$37,$B46)<>0,1/INDEX($C$38:$L$47,G$37,$B46),0) -> 0 | H46: =IF(INDEX($C$38:$L$47,H$37,$B46)<>0,1/INDEX($C$38:$L$47,H$37,$B46),0) -> 0 | I46: =IF(INDEX($C$38:$L$47,I$37,$B46)<>0,1/INDEX($C$38:$L$47,I$37,$B46),0) -> 0 | J46: =IF(INDEX($C$38:$L$47,J$37,$B46)<>0,1/INDEX($C$38:$L$47,J$37,$B46),0) -> 0 | K46: 1 | L46: =IF(L58<>0,IF(L58>=1, CHOOSE( $K$5, L58, LOG(L58+1,2), SQRT(L58), 9/(10-L58), (9+($B$5-1)*L58)/(9+$B$5-L58), L58^2, 2^(L58-1),L58^(1+LN($B$5-1)/LN(9))), CHOOSE( $K$5, 1/L58, LOG(1/L58+1,2), SQRT(1/L58), 9/(10-1/L58), (9+($B$5-1)/L58)/(9+$B$5-1/L58), (1/L58)^2, 2^(1/L58-1),(1/L58)^(1+LN($B$5-1)/LN(9)))^-1),0) -> 0 | O46: 2.8277089e-11 | AB46: =IF(OR($B46>$B$5,AB$37>$B$5),0,(LN(OFFSET($B$37,$B46,AB$37))-LN(OFFSET($O$37,$B46,0)/OFFSET($O$37,AB$37,0)))^2) -> 0 | AC46: =SUM(T46:AB46) -> 0
A47: 0 | B47: 10 | C47: =IF(INDEX($C$38:$L$47,C$37,$B47)<>0,1/INDEX($C$38:$L$47,C$37,$B47),0) -> 0 | D47: =IF(INDEX($C$38:$L$47,D$37,$B47)<>0,1/INDEX($C$38:$L$47,D$37,$B47),0) -> 0 | E47: =IF(INDEX($C$38:$L$47,E$37,$B47)<>0,1/INDEX($C$38:$L$47,E$37,$B47),0) -> 0 | F47: =IF(INDEX($C$38:$L$47,F$37,$B47)<>0,1/INDEX($C$38:$L$47,F$37,$B47),0) -> 0 | G47: =IF(INDEX($C$38:$L$47,G$37,$B47)<>0,1/INDEX($C$38:$L$47,G$37,$B47),0) -> 0 | H47: =IF(INDEX($C$38:$L$47,H$37,$B47)<>0,1/INDEX($C$38:$L$47,H$37,$B47),0) -> 0 | I47: =IF(INDEX($C$38:$L$47,I$37,$B47)<>0,1/INDEX($C$38:$L$47,I$37,$B47),0) -> 0 | J47: =IF(INDEX($C$38:$L$47,J$37,$B47)<>0,1/INDEX($C$38:$L$47,J$37,$B47),0) -> 0 | K47: =IF(INDEX($C$38:$L$47,K$37,$B47)<>0,1/INDEX($C$38:$L$47,K$37,$B47),0) -> 0 | L47: 1 | O47: 2.8277089e-11
T48: Error calculation EVM (Tomashevskii)
C49: 1 | D49: 2 | E49: 3 | F49: 4 | G49: 5 | H49: 6 | I49: 7 | J49: 8 | K49: 9 | L49: 10 | S49: i: | T49: 1 | U49: 2 | V49: 3 | W49: 4 | X49: 5 | Y49: 6 | Z49: 7 | AA49: 8 | AB49: 9 | AC49: 10
A50: Unscaled | B50: 1 | C50: {=CHOOSE(p_sel+1,m_p0,m_p1,m_p2,m_p3,m_p4,m_p5,m_p6,m_p7,m_p8,m_p9,m_p10,m_p11,m_p12,m_p13,m_p14,m_p15,m_p16,m_p17,m_p18,m_p19,m_p20)} -> 0 | D50: 1.7826025 | E50: 0.83255321 | F50: 0 | G50: 0 | H50: 0 | I50: 0 | J50: 0 | K50: 0 | L50: 0 | S50: 1 | T50: =IF(OR($S50>$B$5,T$49>$B$5),"-",$B$5/$L$30*INDEX($C$38:$L$47,$S50,T$49)*INDEX($O$38:$O$47,T$49,0)) -> 0.3677158 | U50: =IF(OR($S50>$B$5,U$49>$B$5),"-",$B$5/$L$30*INDEX($C$38:$L$47,$S50,U$49)*INDEX($O$38:$O$47,U$49,0)) -> 0.40158829 | V50: =IF(OR($S50>$B$5,V$49>$B$5),"-",$B$5/$L$30*INDEX($C$38:$L$47,$S50,V$49)*INDEX($O$38:$O$47,V$49,0)) -> 0.33670033 | W50: =IF(OR($S50>$B$5,W$49>$B$5),"-",$B$5/$L$30*INDEX($C$38:$L$47,$S50,W$49)*INDEX($O$38:$O$47,W$49,0)) -> - | X50: =IF(OR($S50>$B$5,X$49>$B$5),"-",$B$5/$L$30*INDEX($C$38:$L$47,$S50,X$49)*INDEX($O$38:$O$47,X$49,0)) -> - | Y50: =IF(OR($S50>$B$5,Y$49>$B$5),"-",$B$5/$L$30*INDEX($C$38:$L$47,$S50,Y$49)*INDEX($O$38:$O$47,Y$49,0)) -> - | Z50: =IF(OR($S50>$B$5,Z$49>$B$5),"-",$B$5/$L$30*INDEX($C$38:$L$47,$S50,Z$49)*INDEX($O$38:$O$47,Z$49,0)) -> - | AA50: =IF(OR($S50>$B$5,AA$49>$B$5),"-",$B$5/$L$30*INDEX($C$38:$L$47,$S50,AA$49)*INDEX($O$38:$O$47,AA$49,0)) -> - | ... AC50: =IF(OR($S50>$B$5,AC$49>$B$5),"-",$B$5/$L$30*INDEX($C$38:$L$47,$S50,AC$49)*INDEX($O$38:$O$47,AC$49,0)) -> -
B51: 2 | C51: 0.56097757 | D51: 0 | E51: 0.60836434 | F51: 0 | G51: 0 | H51: 0 | I51: 0 | J51: 0 | K51: 0 | L51: 0 | S51: 2 | T51: =IF(OR($S51>$B$5,T$49>$B$5),"-",$B$5/$L$30*INDEX($C$38:$L$47,$S51,T$49)*INDEX($O$38:$O$47,T$49,0)) -> 0.20628032 | U51: =IF(OR($S51>$B$5,U$49>$B$5),"-",$B$5/$L$30*INDEX($C$38:$L$47,$S51,U$49)*INDEX($O$38:$O$47,U$49,0)) -> 0.22528202 | V51: =IF(OR($S51>$B$5,V$49>$B$5),"-",$B$5/$L$30*INDEX($C$38:$L$47,$S51,V$49)*INDEX($O$38:$O$47,V$49,0)) -> 0.24603409 | W51: =IF(OR($S51>$B$5,W$49>$B$5),"-",$B$5/$L$30*INDEX($C$38:$L$47,$S51,W$49)*INDEX($O$38:$O$47,W$49,0)) -> - | X51: =IF(OR($S51>$B$5,X$49>$B$5),"-",$B$5/$L$30*INDEX($C$38:$L$47,$S51,X$49)*INDEX($O$38:$O$47,X$49,0)) -> - | Y51: =IF(OR($S51>$B$5,Y$49>$B$5),"-",$B$5/$L$30*INDEX($C$38:$L$47,$S51,Y$49)*INDEX($O$38:$O$47,Y$49,0)) -> - | Z51: =IF(OR($S51>$B$5,Z$49>$B$5),"-",$B$5/$L$30*INDEX($C$38:$L$47,$S51,Z$49)*INDEX($O$38:$O$47,Z$49,0)) -> - | AA51: =IF(OR($S51>$B$5,AA$49>$B$5),"-",$B$5/$L$30*INDEX($C$38:$L$47,$S51,AA$49)*INDEX($O$38:$O$47,AA$49,0)) -> - | ... AC51: =IF(OR($S51>$B$5,AC$49>$B$5),"-",$B$5/$L$30*INDEX($C$38:$L$47,$S51,AC$49)*INDEX($O$38:$O$47,AC$49,0)) -> -
B52: 3 | C52: 1.2011244 | D52: 1.6437518 | E52: 0 | F52: 0 | G52: 0 | H52: 0 | I52: 0 | J52: 0 | K52: 0 | L52: 0 | S52: 3 | T52: =IF(OR($S52>$B$5,T$49>$B$5),"-",$B$5/$L$30*INDEX($C$38:$L$47,$S52,T$49)*INDEX($O$38:$O$47,T$49,0)) -> 0.44167243 | U52: =IF(OR($S52>$B$5,U$49>$B$5),"-",$B$5/$L$30*INDEX($C$38:$L$47,$S52,U$49)*INDEX($O$38:$O$47,U$49,0)) -> 0.37030774 | V52: =IF(OR($S52>$B$5,V$49>$B$5),"-",$B$5/$L$30*INDEX($C$38:$L$47,$S52,V$49)*INDEX($O$38:$O$47,V$49,0)) -> 0.40441899 | W52: =IF(OR($S52>$B$5,W$49>$B$5),"-",$B$5/$L$30*INDEX($C$38:$L$47,$S52,W$49)*INDEX($O$38:$O$47,W$49,0)) -> - | X52: =IF(OR($S52>$B$5,X$49>$B$5),"-",$B$5/$L$30*INDEX($C$38:$L$47,$S52,X$49)*INDEX($O$38:$O$47,X$49,0)) -> - | Y52: =IF(OR($S52>$B$5,Y$49>$B$5),"-",$B$5/$L$30*INDEX($C$38:$L$47,$S52,Y$49)*INDEX($O$38:$O$47,Y$49,0)) -> - | Z52: =IF(OR($S52>$B$5,Z$49>$B$5),"-",$B$5/$L$30*INDEX($C$38:$L$47,$S52,Z$49)*INDEX($O$38:$O$47,Z$49,0)) -> - | AA52: =IF(OR($S52>$B$5,AA$49>$B$5),"-",$B$5/$L$30*INDEX($C$38:$L$47,$S52,AA$49)*INDEX($O$38:$O$47,AA$49,0)) -> - | ... AC52: =IF(OR($S52>$B$5,AC$49>$B$5),"-",$B$5/$L$30*INDEX($C$38:$L$47,$S52,AC$49)*INDEX($O$38:$O$47,AC$49,0)) -> -
...

Sheet In1
A1: AHP Analytic Hierarchy Process | J1: n= | K1: =Summary!B5 -> 3 | N1: Input | O1: 1
A2: Objective: | D2: =Summary!B11 -> Comparing Smoothness Factor Among Conventional Checkout, Self-Checkout and Unmanned Shop
A5: n | B5: Criteria | G5: Comment | O5: RGMM | P5: +/-
A6: 1 | B6: =IF(ISBLANK(Summary!C18),"",Summary!C18) -> Conventional Cashier | G6: =IF(ISBLANK(Summary!F18),"",Summary!F18) | O6: =O91/O$101 -> 0.42857143 | P6: =N91*SINH(P79)/O$101 -> 1.3457935e-16
A7: 2 | B7: =IF(ISBLANK(Summary!C19),"",Summary!C19) -> Self-Checkout | G7: =IF(ISBLANK(Summary!F19),"",Summary!F19) | O7: =O92/O$101 -> 0.14285714 | P7: =N92*SINH(P80)/O$101 -> 3.1720658e-17
A8: 3 | B8: =IF(ISBLANK(Summary!C20),"",Summary!C20) -> Unmanned Shop | G8: =IF(ISBLANK(Summary!F20),"",Summary!F20) | O8: =O93/O$101 -> 0.42857143 | P8: =N93*SINH(P81)/O$101 -> 1.3457935e-16
A9: 4 | B9: =IF(ISBLANK(Summary!C21),"",Summary!C21) | G9: =IF(ISBLANK(Summary!F21),"",Summary!F21) | O9: =O94/O$101 -> 0 | P9: =N94*SINH(P82)/O$101 -> 0
A10: 5 | B10: =IF(ISBLANK(Summary!C22),"",Summary!C22) | G10: =IF(ISBLANK(Summary!F22),"",Summary!F22) | O10: =O95/O$101 -> 0 | P10: =N95*SINH(P83)/O$101 -> 0
A11: 6 | B11: =IF(ISBLANK(Summary!C23),"",Summary!C23) | G11: =IF(ISBLANK(Summary!F23),"",Summary!F23) | O11: =O96/O$101 -> 0 | P11: =N96*SINH(P84)/O$101 -> 0
A12: 7 | B12: =IF(ISBLANK(Summary!C24),"",Summary!C24) | G12: =IF(ISBLANK(Summary!F24),"",Summary!F24) | O12: =O97/O$101 -> 0 | P12: =N97*SINH(P85)/O$101 -> 0
A13: 8 | B13: =IF(ISBLANK(Summary!C25),"",Summary!C25) | G13: =IF(ISBLANK(Summary!F25),"",Summary!F25) | O13: =O98/O$101 -> 0 | P13: =N98*SINH(P86)/O$101 -> 0
A14: 9 | B14: =IF(ISBLANK(Summary!C26),"",Summary!C26) | G14: =IF(ISBLANK(Summary!F26),"",Summary!F26) -> for 9&10 unprotect the input sheets and expand the | O14: =O99/O$101 -> 0 | P14: =N99*SINH(P87)/O$101 -> 0
A15: 10 | B15: =IF(ISBLANK(Summary!C27),"",Summary!C27) | G15: =IF(ISBLANK(Summary!F27),"",Summary!F27) -> question section ("+" in row 66) | O15: =O100/O$101 -> 0 | P15: =N100*SINH(P88)/O$101 -> 0
B17: Participant 1 | F17: 1 | J17: a: | K17: =Summary!K7 -> 0.1 | L17: CR: | M17: =(N101-K1)/((2.7699*K1-4.3513)-K1) -> -1.8534608e-15 | O17: =Summary!K5 -> 1
B18: Name | F18: Weight | H18: Date | M18: Consistency Ratio
G19: Criteria | K19: more important ? | L19: Scale | O19: A
B20: i | C20: j | D20: A | H20: B | K20: - A or B | L20: (1-9) | O20: B
A21: =IF(AND(B21<=$K$1,C21<=$K$1),B21*10+C21,0) -> 12 | B21: 1 | C21: 2 | D21: =VLOOKUP($B21,$A$6:$D$15,2) -> Conventional Cashier | H21: =IF(B21>0,VLOOKUP($C21,$A$6:$D$15,2),"") -> Self-Checkout | K21: A | L21: 3 | M21: =IF(AND(P21<>0,L$66>=($K$1*($K$1-1)/2)),RANK(P21,P$21:P$65),"") | N21: =IF(M21<4,OFFSET($B$123,$B21,$C21),"") | O21: =IF(AND(L21<>"",K21<>""),L21^(IF(K21="a",1,-1)),1) -> 3 | P21: =IF(AND($M$17>=$K$17,$A21>0),OFFSET($B$101,$B21,$C21),0) -> 0
A22: =IF(AND(B22<=$K$1,C22<=$K$1),B22*10+C22,0) -> 13 | B22: 1 | C22: 3 | D22: =IF(OR(B22=B21,A22=0),"",VLOOKUP($B22,$A$6:$D$15,2)) | H22: =IF(B22>0,VLOOKUP($C22,$A$6:$D$15,2),"") -> Unmanned Shop | K22: A | L22: 1 | M22: =IF(AND(P22<>0,L$66>=($K$1*($K$1-1)/2)),RANK(P22,P$21:P$65),"") | N22: =IF(M22<4,OFFSET($B$123,$B22,$C22),"") | O22: =IF(AND(L22<>"",K22<>""),L22^(IF(K22="a",1,-1)),1) -> 1 | P22: =IF(AND($M$17>=$K$17,$A22>0),OFFSET($B$101,$B22,$C22),0) -> 0
A23: =IF(AND(B23<=$K$1,C23<=$K$1),B23*10+C23,0) -> 0 | B23: 1 | C23: 4 | D23: =IF(OR(B23=B22,A23=0),"",VLOOKUP($B23,$A$6:$D$15,2)) | H23: =IF(B23>0,VLOOKUP($C23,$A$6:$D$15,2),"") | M23: =IF(AND(P23<>0,L$66>=($K$1*($K$1-1)/2)),RANK(P23,P$21:P$65),"") | N23: =IF(M23<4,OFFSET($B$123,$B23,$C23),"") | O23: =IF(AND(L23<>"",K23<>""),L23^(IF(K23="a",1,-1)),1) -> 1 | P23: =IF(AND($M$17>=$K$17,$A23>0),OFFSET($B$101,$B23,$C23),0) -> 0
A24: =IF(AND(B24<=$K$1,C24<=$K$1),B24*10+C24,0) -> 0 | B24: 1 | C24: 5 | D24: =IF(OR(B24=B23,A24=0),"",VLOOKUP($B24,$A$6:$D$15,2)) | H24: =IF(B24>0,VLOOKUP($C24,$A$6:$D$15,2),"") | M24: =IF(AND(P24<>0,L$66>=($K$1*($K$1-1)/2)),RANK(P24,P$21:P$65),"") | N24: =IF(M24<4,OFFSET($B$123,$B24,$C24),"") | O24: =IF(AND(L24<>"",K24<>""),L24^(IF(K24="a",1,-1)),1) -> 1 | P24: =IF(AND($M$17>=$K$17,$A24>0),OFFSET($B$101,$B24,$C24),0) -> 0
A25: =IF(AND(B25<=$K$1,C25<=$K$1),B25*10+C25,0) -> 0 | B25: 1 | C25: 6 | D25: =IF(OR(B25=B24,A25=0),"",VLOOKUP($B25,$A$6:$D$15,2)) | H25: =IF(B25>0,VLOOKUP($C25,$A$6:$D$15,2),"") | M25: =IF(AND(P25<>0,L$66>=($K$1*($K$1-1)/2)),RANK(P25,P$21:P$65),"") | N25: =IF(M25<4,OFFSET($B$123,$B25,$C25),"") | O25: =IF(AND(L25<>"",K25<>""),L25^(IF(K25="a",1,-1)),1) -> 1 | P25: =IF(AND($M$17>=$K$17,$A25>0),OFFSET($B$101,$B25,$C25),0) -> 0
A26: =IF(AND(B26<=$K$1,C26<=$K$1),B26*10+C26,0) -> 0 | B26: 1 | C26: 7 | D26: =IF(OR(B26=B25,A26=0),"",VLOOKUP($B26,$A$6:$D$15,2)) | H26: =IF(B26>0,VLOOKUP($C26,$A$6:$D$15,2),"") | M26: =IF(AND(P26<>0,L$66>=($K$1*($K$1-1)/2)),RANK(P26,P$21:P$65),"") | N26: =IF(M26<4,OFFSET($B$123,$B26,$C26),"") | O26: =IF(AND(L26<>"",K26<>""),L26^(IF(K26="a",1,-1)),1) -> 1 | P26: =IF(AND($M$17>=$K$17,$A26>0),OFFSET($B$101,$B26,$C26),0) -> 0
A27: =IF(AND(B27<=$K$1,C27<=$K$1),B27*10+C27,0) -> 0 | B27: 1 | C27: 8 | D27: =IF(OR(B27=B26,A27=0),"",VLOOKUP($B27,$A$6:$D$15,2)) | H27: =IF(B27>0,VLOOKUP($C27,$A$6:$D$15,2),"") | M27: =IF(AND(P27<>0,L$66>=($K$1*($K$1-1)/2)),RANK(P27,P$21:P$65),"") | N27: =IF(M27<4,OFFSET($B$123,$B27,$C27),"") | O27: =IF(AND(L27<>"",K27<>""),L27^(IF(K27="a",1,-1)),1) -> 1 | P27: =IF(AND($M$17>=$K$17,$A27>0),OFFSET($B$101,$B27,$C27),0) -> 0
A28: =IF(AND(B28<=$K$1,C28<=$K$1),B28*10+C28,0) -> 23 | B28: 2 | C28: 3 | D28: =IF(OR(B28=B27,A28=0),"",VLOOKUP($B28,$A$6:$D$15,2)) -> Self-Checkout | H28: =IF(B28>0,VLOOKUP($C28,$A$6:$D$15,2),"") -> Unmanned Shop | K28: B | L28: 3 | M28: =IF(AND(P28<>0,L$66>=($K$1*($K$1-1)/2)),RANK(P28,P$21:P$65),"") | N28: =IF(M28<4,OFFSET($B$123,$B28,$C28),"") | O28: =IF(AND(L28<>"",K28<>""),L28^(IF(K28="a",1,-1)),1) -> 0.33333333 | P28: =IF(AND($M$17>=$K$17,$A28>0),OFFSET($B$101,$B28,$C28),0) -> 0
A29: =IF(AND(B29<=$K$1,C29<=$K$1),B29*10+C29,0) -> 0 | B29: 2 | C29: 4 | D29: =IF(OR(B29=B28,A29=0),"",VLOOKUP($B29,$A$6:$D$15,2)) | H29: =IF(B29>0,VLOOKUP($C29,$A$6:$D$15,2),"") | M29: =IF(AND(P29<>0,L$66>=($K$1*($K$1-1)/2)),RANK(P29,P$21:P$65),"") | N29: =IF(M29<4,OFFSET($B$123,$B29,$C29),"") | O29: =IF(AND(L29<>"",K29<>""),L29^(IF(K29="a",1,-1)),1) -> 1 | P29: =IF(AND($M$17>=$K$17,$A29>0),OFFSET($B$101,$B29,$C29),0) -> 0
A30: =IF(AND(B30<=$K$1,C30<=$K$1),B30*10+C30,0) -> 0 | B30: 2 | C30: 5 | D30: =IF(OR(B30=B29,A30=0),"",VLOOKUP($B30,$A$6:$D$15,2)) | H30: =IF(B30>0,VLOOKUP($C30,$A$6:$D$15,2),"") | M30: =IF(AND(P30<>0,L$66>=($K$1*($K$1-1)/2)),RANK(P30,P$21:P$65),"") | N30: =IF(M30<4,OFFSET($B$123,$B30,$C30),"") | O30: =IF(AND(L30<>"",K30<>""),L30^(IF(K30="a",1,-1)),1) -> 1 | P30: =IF(AND($M$17>=$K$17,$A30>0),OFFSET($B$101,$B30,$C30),0) -> 0
A31: =IF(AND(B31<=$K$1,C31<=$K$1),B31*10+C31,0) -> 0 | B31: 2 | C31: 6 | D31: =IF(OR(B31=B30,A31=0),"",VLOOKUP($B31,$A$6:$D$15,2)) | H31: =IF(B31>0,VLOOKUP($C31,$A$6:$D$15,2),"") | M31: =IF(AND(P31<>0,L$66>=($K$1*($K$1-1)/2)),RANK(P31,P$21:P$65),"") | N31: =IF(M31<4,OFFSET($B$123,$B31,$C31),"") | O31: =IF(AND(L31<>"",K31<>""),L31^(IF(K31="a",1,-1)),1) -> 1 | P31: =IF(AND($M$17>=$K$17,$A31>0),OFFSET($B$101,$B31,$C31),0) -> 0
A32: =IF(AND(B32<=$K$1,C32<=$K$1),B32*10+C32,0) -> 0 | B32: 2 | C32: 7 | D32: =IF(OR(B32=B31,A32=0),"",VLOOKUP($B32,$A$6:$D$15,2)) | H32: =IF(B32>0,VLOOKUP($C32,$A$6:$D$15,2),"") | M32: =IF(AND(P32<>0,L$66>=($K$1*($K$1-1)/2)),RANK(P32,P$21:P$65),"") | N32: =IF(M32<4,OFFSET($B$123,$B32,$C32),"") | O32: =IF(AND(L32<>"",K32<>""),L32^(IF(K32="a",1,-1)),1) -> 1 | P32: =IF(AND($M$17>=$K$17,$A32>0),OFFSET($B$101,$B32,$C32),0) -> 0
A33: =IF(AND(B33<=$K$1,C33<=$K$1),B33*10+C33,0) -> 0 | B33: 2 | C33: 8 | D33: =IF(OR(B33=B32,A33=0),"",VLOOKUP($B33,$A$6:$D$15,2)) | H33: =IF(B33>0,VLOOKUP($C33,$A$6:$D$15,2),"") | M33: =IF(AND(P33<>0,L$66>=($K$1*($K$1-1)/2)),RANK(P33,P$21:P$65),"") | N33: =IF(M33<4,OFFSET($B$123,$B33,$C33),"") | O33: =IF(AND(L33<>"",K33<>""),L33^(IF(K33="a",1,-1)),1) -> 1 | P33: =IF(AND($M$17>=$K$17,$A33>0),OFFSET($B$101,$B33,$C33),0) -> 0
A34: =IF(AND(B34<=$K$1,C34<=$K$1),B34*10+C34,0) -> 0 | B34: 3 | C34: 4 | D34: =IF(OR(B34=B33,A34=0),"",VLOOKUP($B34,$A$6:$D$15,2)) | H34: =IF(B34>0,VLOOKUP($C34,$A$6:$D$15,2),"") | M34: =IF(AND(P34<>0,L$66>=($K$1*($K$1-1)/2)),RANK(P34,P$21:P$65),"") | N34: =IF(M34<4,OFFSET($B$123,$B34,$C34),"") | O34: =IF(AND(L34<>"",K34<>""),L34^(IF(K34="a",1,-1)),1) -> 1 | P34: =IF(AND($M$17>=$K$17,$A34>0),OFFSET($B$101,$B34,$C34),0) -> 0
A35: =IF(AND(B35<=$K$1,C35<=$K$1),B35*10+C35,0) -> 0 | B35: 3 | C35: 5 | D35: =IF(OR(B35=B34,A35=0),"",VLOOKUP($B35,$A$6:$D$15,2)) | H35: =IF(B35>0,VLOOKUP($C35,$A$6:$D$15,2),"") | M35: =IF(AND(P35<>0,L$66>=($K$1*($K$1-1)/2)),RANK(P35,P$21:P$65),"") | N35: =IF(M35<4,OFFSET($B$123,$B35,$C35),"") | O35: =IF(AND(L35<>"",K35<>""),L35^(IF(K35="a",1,-1)),1) -> 1 | P35: =IF(AND($M$17>=$K$17,$A35>0),OFFSET($B$101,$B35,$C35),0) -> 0
A36: =IF(AND(B36<=$K$1,C36<=$K$1),B36*10+C36,0) -> 0 | B36: 3 | C36: 6 | D36: =IF(OR(B36=B35,A36=0),"",VLOOKUP($B36,$A$6:$D$15,2)) | H36: =IF(B36>0,VLOOKUP($C36,$A$6:$D$15,2),"") | M36: =IF(AND(P36<>0,L$66>=($K$1*($K$1-1)/2)),RANK(P36,P$21:P$65),"") | N36: =IF(M36<4,OFFSET($B$123,$B36,$C36),"") | O36: =IF(AND(L36<>"",K36<>""),L36^(IF(K36="a",1,-1)),1) -> 1 | P36: =IF(AND($M$17>=$K$17,$A36>0),OFFSET($B$101,$B36,$C36),0) -> 0
A37: =IF(AND(B37<=$K$1,C37<=$K$1),B37*10+C37,0) -> 0 | B37: 3 | C37: 7 | D37: =IF(OR(B37=B36,A37=0),"",VLOOKUP($B37,$A$6:$D$15,2)) | H37: =IF(B37>0,VLOOKUP($C37,$A$6:$D$15,2),"") | M37: =IF(AND(P37<>0,L$66>=($K$1*($K$1-1)/2)),RANK(P37,P$21:P$65),"") | N37: =IF(M37<4,OFFSET($B$123,$B37,$C37),"") | O37: =IF(AND(L37<>"",K37<>""),L37^(IF(K37="a",1,-1)),1) -> 1 | P37: =IF(AND($M$17>=$K$17,$A37>0),OFFSET($B$101,$B37,$C37),0) -> 0
A38: =IF(AND(B38<=$K$1,C38<=$K$1),B38*10+C38,0) -> 0 | B38: 3 | C38: 8 | D38: =IF(OR(B38=B37,A38=0),"",VLOOKUP($B38,$A$6:$D$15,2)) | H38: =IF(B38>0,VLOOKUP($C38,$A$6:$D$15,2),"") | M38: =IF(AND(P38<>0,L$66>=($K$1*($K$1-1)/2)),RANK(P38,P$21:P$65),"") | N38: =IF(M38<4,OFFSET($B$123,$B38,$C38),"") | O38: =IF(AND(L38<>"",K38<>""),L38^(IF(K38="a",1,-1)),1) -> 1 | P38: =IF(AND($M$17>=$K$17,$A38>0),OFFSET($B$101,$B38,$C38),0) -> 0
A39: =IF(AND(B39<=$K$1,C39<=$K$1),B39*10+C39,0) -> 0 | B39: 4 | C39: 5 | D39: =IF(OR(B39=B38,A39=0),"",VLOOKUP($B39,$A$6:$D$15,2)) | H39: =IF(B39>0,VLOOKUP($C39,$A$6:$D$15,2),"") | M39: =IF(AND(P39<>0,L$66>=($K$1*($K$1-1)/2)),RANK(P39,P$21:P$65),"") | N39: =IF(M39<4,OFFSET($B$123,$B39,$C39),"") | O39: =IF(AND(L39<>"",K39<>""),L39^(IF(K39="a",1,-1)),1) -> 1 | P39: =IF(AND($M$17>=$K$17,$A39>0),OFFSET($B$101,$B39,$C39),0) -> 0
A40: =IF(AND(B40<=$K$1,C40<=$K$1),B40*10+C40,0) -> 0 | B40: 4 | C40: 6 | D40: =IF(OR(B40=B39,A40=0),"",VLOOKUP($B40,$A$6:$D$15,2)) | H40: =IF(B40>0,VLOOKUP($C40,$A$6:$D$15,2),"") | M40: =IF(AND(P40<>0,L$66>=($K$1*($K$1-1)/2)),RANK(P40,P$21:P$65),"") | N40: =IF(M40<4,OFFSET($B$123,$B40,$C40),"") | O40: =IF(AND(L40<>"",K40<>""),L40^(IF(K40="a",1,-1)),1) -> 1 | P40: =IF(AND($M$17>=$K$17,$A40>0),OFFSET($B$101,$B40,$C40),0) -> 0
... A65: =IF(AND(B65<=$K$1,C65<=$K$1),B65*10+C65,0) -> 0 | B65: 9 | C65: 10 | D65: =IF(OR(B65=B64,A65=0),"",VLOOKUP($B65,$A$6:$D$15,2)) | H65: =IF(B65>0,VLOOKUP($C65,$A$6:$D$15,2),"") | M65: =IF(AND(P65<>0,L$66>=($K$1*($K$1-1)/2)),RANK(P65,P$21:P$65),"") | N65: =IF(M65<4,OFFSET($B$123,$B65,$C65),"") | O65: =IF(AND(L65<>"",K65<>""),L65^(IF(K65="a",1,-1)),1) -> 1 | P65: =IF(AND($M$17>=$K$17,$A65>0),OFFSET($B$101,$B65,$C65),0) -> 0
K66: =COUNT(K21:K65) -> 0 | L66: =COUNT(L21:L65) -> 3
A67: Intensity of importance | D67: Definition | G67: Explanation
...

Sheet In2
A1: AHP Analytic Hierarchy Process | J1: n= | K1: =Summary!B5 -> 3 | N1: Input | O1: 2
A2: Objective: | D2: =Summary!B11 -> Comparing Smoothness Factor Among Conventional Checkout, Self-Checkout and Unmanned Shop
A5: n | B5: Criteria | G5: Comment | O5: RGMM | P5: +/-
A6: 1 | B6: =IF(ISBLANK(Summary!C18),"",Summary!C18) -> Conventional Cashier | G6: =IF(ISBLANK(Summary!F18),"",Summary!F18) | O6: =O91/O$101 -> 0.49338597 | P6: =N91*SINH(P79)/O$101 -> 0.11201025
A7: 2 | B7: =IF(ISBLANK(Summary!C19),"",Summary!C19) -> Self-Checkout | G7: =IF(ISBLANK(Summary!F19),"",Summary!F19) | O7: =O92/O$101 -> 0.19580035 | P7: =N92*SINH(P80)/O$101 -> 0.044451297
A8: 3 | B8: =IF(ISBLANK(Summary!C20),"",Summary!C20) -> Unmanned Shop | G8: =IF(ISBLANK(Summary!F20),"",Summary!F20) | O8: =O93/O$101 -> 0.31081368 | P8: =N93*SINH(P81)/O$101 -> 0.070562035
A9: 4 | B9: =IF(ISBLANK(Summary!C21),"",Summary!C21) | G9: =IF(ISBLANK(Summary!F21),"",Summary!F21) | O9: =O94/O$101 -> 0 | P9: =N94*SINH(P82)/O$101 -> 0
A10: 5 | B10: =IF(ISBLANK(Summary!C22),"",Summary!C22) | G10: =IF(ISBLANK(Summary!F22),"",Summary!F22) | O10: =O95/O$101 -> 0 | P10: =N95*SINH(P83)/O$101 -> 0
A11: 6 | B11: =IF(ISBLANK(Summary!C23),"",Summary!C23) | G11: =IF(ISBLANK(Summary!F23),"",Summary!F23) | O11: =O96/O$101 -> 0 | P11: =N96*SINH(P84)/O$101 -> 0
A12: 7 | B12: =IF(ISBLANK(Summary!C24),"",Summary!C24) | G12: =IF(ISBLANK(Summary!F24),"",Summary!F24) | O12: =O97/O$101 -> 0 | P12: =N97*SINH(P85)/O$101 -> 0
A13: 8 | B13: =IF(ISBLANK(Summary!C25),"",Summary!C25) | G13: =IF(ISBLANK(Summary!F25),"",Summary!F25) | O13: =O98/O$101 -> 0 | P13: =N98*SINH(P86)/O$101 -> 0
A14: 9 | B14: =IF(ISBLANK(Summary!C26),"",Summary!C26) | G14: =IF(ISBLANK(Summary!F26),"",Summary!F26) -> for 9&10 unprotect the input sheets and expand the | O14: =O99/O$101 -> 0 | P14: =N99*SINH(P87)/O$101 -> 0
A15: 10 | B15: =IF(ISBLANK(Summary!C27),"",Summary!C27) | G15: =IF(ISBLANK(Summary!F27),"",Summary!F27) -> question section ("+" in row 66) | O15: =O100/O$101 -> 0 | P15: =N100*SINH(P88)/O$101 -> 0
B17: Participant 2 | F17: 1 | J17: a: | K17: =Summary!K7 -> 0.1 | L17: CR: | M17: =(N101-K1)/((2.7699*K1-4.3513)-K1) -> 0.055949057 | O17: =Summary!K5 -> 1
B18: Name | F18: Weight | H18: Date | M18: Consistency Ratio
G19: Criteria | K19: more important ? | L19: Scale | O19: A
B20: i | C20: j | D20: A | H20: B | K20: - A or B | L20: (1-9) | O20: B
A21: =IF(AND(B21<=$K$1,C21<=$K$1),B21*10+C21,0) -> 12 | B21: 1 | C21: 2 | D21: =VLOOKUP($B21,$A$6:$D$15,2) -> Conventional Cashier | H21: =IF(B21>0,VLOOKUP($C21,$A$6:$D$15,2),"") -> Self-Checkout | K21: A | L21: 2 | M21: =IF(AND(P21<>0,L$66>=($K$1*($K$1-1)/2)),RANK(P21,P$21:P$65),"") | N21: =IF(M21<4,OFFSET($B$123,$B21,$C21),"") | O21: =IF(AND(L21<>"",K21<>""),L21^(IF(K21="a",1,-1)),1) -> 2 | P21: =IF(AND($M$17>=$K$17,$A21>0),OFFSET($B$101,$B21,$C21),0) -> 0
A22: =IF(AND(B22<=$K$1,C22<=$K$1),B22*10+C22,0) -> 13 | B22: 1 | C22: 3 | D22: =IF(OR(B22=B21,A22=0),"",VLOOKUP($B22,$A$6:$D$15,2)) | H22: =IF(B22>0,VLOOKUP($C22,$A$6:$D$15,2),"") -> Unmanned Shop | K22: A | L22: 2 | M22: =IF(AND(P22<>0,L$66>=($K$1*($K$1-1)/2)),RANK(P22,P$21:P$65),"") | N22: =IF(M22<4,OFFSET($B$123,$B22,$C22),"") | O22: =IF(AND(L22<>"",K22<>""),L22^(IF(K22="a",1,-1)),1) -> 2 | P22: =IF(AND($M$17>=$K$17,$A22>0),OFFSET($B$101,$B22,$C22),0) -> 0
A23: =IF(AND(B23<=$K$1,C23<=$K$1),B23*10+C23,0) -> 0 | B23: 1 | C23: 4 | D23: =IF(OR(B23=B22,A23=0),"",VLOOKUP($B23,$A$6:$D$15,2)) | H23: =IF(B23>0,VLOOKUP($C23,$A$6:$D$15,2),"") | M23: =IF(AND(P23<>0,L$66>=($K$1*($K$1-1)/2)),RANK(P23,P$21:P$65),"") | N23: =IF(M23<4,OFFSET($B$123,$B23,$C23),"") | O23: =IF(AND(L23<>"",K23<>""),L23^(IF(K23="a",1,-1)),1) -> 1 | P23: =IF(AND($M$17>=$K$17,$A23>0),OFFSET($B$101,$B23,$C23),0) -> 0
A24: =IF(AND(B24<=$K$1,C24<=$K$1),B24*10+C24,0) -> 0 | B24: 1 | C24: 5 | D24: =IF(OR(B24=B23,A24=0),"",VLOOKUP($B24,$A$6:$D$15,2)) | H24: =IF(B24>0,VLOOKUP($C24,$A$6:$D$15,2),"") | M24: =IF(AND(P24<>0,L$66>=($K$1*($K$1-1)/2)),RANK(P24,P$21:P$65),"") | N24: =IF(M24<4,OFFSET($B$123,$B24,$C24),"") | O24: =IF(AND(L24<>"",K24<>""),L24^(IF(K24="a",1,-1)),1) -> 1 | P24: =IF(AND($M$17>=$K$17,$A24>0),OFFSET($B$101,$B24,$C24),0) -> 0
A25: =IF(AND(B25<=$K$1,C25<=$K$1),B25*10+C25,0) -> 0 | B25: 1 | C25: 6 | D25: =IF(OR(B25=B24,A25=0),"",VLOOKUP($B25,$A$6:$D$15,2)) | H25: =IF(B25>0,VLOOKUP($C25,$A$6:$D$15,2),"") | M25: =IF(AND(P25<>0,L$66>=($K$1*($K$1-1)/2)),RANK(P25,P$21:P$65),"") | N25: =IF(M25<4,OFFSET($B$123,$B25,$C25),"") | O25: =IF(AND(L25<>"",K25<>""),L25^(IF(K25="a",1,-1)),1) -> 1 | P25: =IF(AND($M$17>=$K$17,$A25>0),OFFSET($B$101,$B25,$C25),0) -> 0
A26: =IF(AND(B26<=$K$1,C26<=$K$1),B26*10+C26,0) -> 0 | B26: 1 | C26: 7 | D26: =IF(OR(B26=B25,A26=0),"",VLOOKUP($B26,$A$6:$D$15,2)) | H26: =IF(B26>0,VLOOKUP($C26,$A$6:$D$15,2),"") | M26: =IF(AND(P26<>0,L$66>=($K$1*($K$1-1)/2)),RANK(P26,P$21:P$65),"") | N26: =IF(M26<4,OFFSET($B$123,$B26,$C26),"") | O26: =IF(AND(L26<>"",K26<>""),L26^(IF(K26="a",1,-1)),1) -> 1 | P26: =IF(AND($M$17>=$K$17,$A26>0),OFFSET($B$101,$B26,$C26),0) -> 0
A27: =IF(AND(B27<=$K$1,C27<=$K$1),B27*10+C27,0) -> 0 | B27: 1 | C27: 8 | D27: =IF(OR(B27=B26,A27=0),"",VLOOKUP($B27,$A$6:$D$15,2)) | H27: =IF(B27>0,VLOOKUP($C27,$A$6:$D$15,2),"") | M27: =IF(AND(P27<>0,L$66>=($K$1*($K$1-1)/2)),RANK(P27,P$21:P$65),"") | N27: =IF(M27<4,OFFSET($B$123,$B27,$C27),"") | O27: =IF(AND(L27<>"",K27<>""),L27^(IF(K27="a",1,-1)),1) -> 1 | P27: =IF(AND($M$17>=$K$17,$A27>0),OFFSET($B$101,$B27,$C27),0) -> 0
A28: =IF(AND(B28<=$K$1,C28<=$K$1),B28*10+C28,0) -> 23 | B28: 2 | C28: 3 | D28: =IF(OR(B28=B27,A28=0),"",VLOOKUP($B28,$A$6:$D$15,2)) -> Self-Checkout | H28: =IF(B28>0,VLOOKUP($C28,$A$6:$D$15,2),"") -> Unmanned Shop | K28: B | L28: 2 | M28: =IF(AND(P28<>0,L$66>=($K$1*($K$1-1)/2)),RANK(P28,P$21:P$65),"") | N28: =IF(M28<4,OFFSET($B$123,$B28,$C28),"") | O28: =IF(AND(L28<>"",K28<>""),L28^(IF(K28="a",1,-1)),1) -> 0.5 | P28: =IF(AND($M$17>=$K$17,$A28>0),OFFSET($B$101,$B28,$C28),0) -> 0
A29: =IF(AND(B29<=$K$1,C29<=$K$1),B29*10+C29,0) -> 0 | B29: 2 | C29: 4 | D29: =IF(OR(B29=B28,A29=0),"",VLOOKUP($B29,$A$6:$D$15,2)) | H29: =IF(B29>0,VLOOKUP($C29,$A$6:$D$15,2),"") | M29: =IF(AND(P29<>0,L$66>=($K$1*($K$1-1)/2)),RANK(P29,P$21:P$65),"") | N29: =IF(M29<4,OFFSET($B$123,$B29,$C29),"") | O29: =IF(AND(L29<>"",K29<>""),L29^(IF(K29="a",1,-1)),1) -> 1 | P29: =IF(AND($M$17>=$K$17,$A29>0),OFFSET($B$101,$B29,$C29),0) -> 0
A30: =IF(AND(B30<=$K$1,C30<=$K$1),B30*10+C30,0) -> 0 | B30: 2 | C30: 5 | D30: =IF(OR(B30=B29,A30=0),"",VLOOKUP($B30,$A$6:$D$15,2)) | H30: =IF(B30>0,VLOOKUP($C30,$A$6:$D$15,2),"") | M30: =IF(AND(P30<>0,L$66>=($K$1*($K$1-1)/2)),RANK(P30,P$21:P$65),"") | N30: =IF(M30<4,OFFSET($B$123,$B30,$C30),"") | O30: =IF(AND(L30<>"",K30<>""),L30^(IF(K30="a",1,-1)),1) -> 1 | P30: =IF(AND($M$17>=$K$17,$A30>0),OFFSET($B$101,$B30,$C30),0) -> 0
A31: =IF(AND(B31<=$K$1,C31<=$K$1),B31*10+C31,0) -> 0 | B31: 2 | C31: 6 | D31: =IF(OR(B31=B30,A31=0),"",VLOOKUP($B31,$A$6:$D$15,2)) | H31: =IF(B31>0,VLOOKUP($C31,$A$6:$D$15,2),"") | M31: =IF(AND(P31<>0,L$66>=($K$1*($K$1-1)/2)),RANK(P31,P$21:P$65),"") | N31: =IF(M31<4,OFFSET($B$123,$B31,$C31),"") | O31: =IF(AND(L31<>"",K31<>""),L31^(IF(K31="a",1,-1)),1) -> 1 | P31: =IF(AND($M$17>=$K$17,$A31>0),OFFSET($B$101,$B31,$C31),0) -> 0
A32: =IF(AND(B32<=$K$1,C32<=$K$1),B32*10+C32,0) -> 0 | B32: 2 | C32: 7 | D32: =IF(OR(B32=B31,A32=0),"",VLOOKUP($B32,$A$6:$D$15,2)) | H32: =IF(B32>0,VLOOKUP($C32,$A$6:$D$15,2),"") | M32: =IF(AND(P32<>0,L$66>=($K$1*($K$1-1)/2)),RANK(P32,P$21:P$65),"") | N32: =IF(M32<4,OFFSET($B$123,$B32,$C32),"") | O32: =IF(AND(L32<>"",K32<>""),L32^(IF(K32="a",1,-1)),1) -> 1 | P32: =IF(AND($M$17>=$K$17,$A32>0),OFFSET($B$101,$B32,$C32),0) -> 0
A33: =IF(AND(B33<=$K$1,C33<=$K$1),B33*10+C33,0) -> 0 | B33: 2 | C33: 8 | D33: =IF(OR(B33=B32,A33=0),"",VLOOKUP($B33,$A$6:$D$15,2)) | H33: =IF(B33>0,VLOOKUP($C33,$A$6:$D$15,2),"") | M33: =IF(AND(P33<>0,L$66>=($K$1*($K$1-1)/2)),RANK(P33,P$21:P$65),"") | N33: =IF(M33<4,OFFSET($B$123,$B33,$C33),"") | O33: =IF(AND(L33<>"",K33<>""),L33^(IF(K33="a",1,-1)),1) -> 1 | P33: =IF(AND($M$17>=$K$17,$A33>0),OFFSET($B$101,$B33,$C33),0) -> 0
A34: =IF(AND(B34<=$K$1,C34<=$K$1),B34*10+C34,0) -> 0 | B34: 3 | C34: 4 | D34: =IF(OR(B34=B33,A34=0),"",VLOOKUP($B34,$A$6:$D$15,2)) | H34: =IF(B34>0,VLOOKUP($C34,$A$6:$D$15,2),"") | M34: =IF(AND(P34<>0,L$66>=($K$1*($K$1-1)/2)),RANK(P34,P$21:P$65),"") | N34: =IF(M34<4,OFFSET($B$123,$B34,$C34),"") | O34: =IF(AND(L34<>"",K34<>""),L34^(IF(K34="a",1,-1)),1) -> 1 | P34: =IF(AND($M$17>=$K$17,$A34>0),OFFSET($B$101,$B34,$C34),0) -> 0
A35: =IF(AND(B35<=$K$1,C35<=$K$1),B35*10+C35,0) -> 0 | B35: 3 | C35: 5 | D35: =IF(OR(B35=B34,A35=0),"",VLOOKUP($B35,$A$6:$D$15,2)) | H35: =IF(B35>0,VLOOKUP($C35,$A$6:$D$15,2),"") | M35: =IF(AND(P35<>0,L$66>=($K$1*($K$1-1)/2)),RANK(P35,P$21:P$65),"") | N35: =IF(M35<4,OFFSET($B$123,$B35,$C35),"") | O35: =IF(AND(L35<>"",K35<>""),L35^(IF(K35="a",1,-1)),1) -> 1 | P35: =IF(AND($M$17>=$K$17,$A35>0),OFFSET($B$101,$B35,$C35),0) -> 0
A36: =IF(AND(B36<=$K$1,C36<=$K$1),B36*10+C36,0) -> 0 | B36: 3 | C36: 6 | D36: =IF(OR(B36=B35,A36=0),"",VLOOKUP($B36,$A$6:$D$15,2)) | H36: =IF(B36>0,VLOOKUP($C36,$A$6:$D$15,2),"") | M36: =IF(AND(P36<>0,L$66>=($K$1*($K$1-1)/2)),RANK(P36,P$21:P$65),"") | N36: =IF(M36<4,OFFSET($B$123,$B36,$C36),"") | O36: =IF(AND(L36<>"",K36<>""),L36^(IF(K36="a",1,-1)),1) -> 1 | P36: =IF(AND($M$17>=$K$17,$A36>0),OFFSET($B$101,$B36,$C36),0) -> 0
A37: =IF(AND(B37<=$K$1,C37<=$K$1),B37*10+C37,0) -> 0 | B37: 3 | C37: 7 | D37: =IF(OR(B37=B36,A37=0),"",VLOOKUP($B37,$A$6:$D$15,2)) | H37: =IF(B37>0,VLOOKUP($C37,$A$6:$D$15,2),"") | M37: =IF(AND(P37<>0,L$66>=($K$1*($K$1-1)/2)),RANK(P37,P$21:P$65),"") | N37: =IF(M37<4,OFFSET($B$123,$B37,$C37),"") | O37: =IF(AND(L37<>"",K37<>""),L37^(IF(K37="a",1,-1)),1) -> 1 | P37: =IF(AND($M$17>=$K$17,$A37>0),OFFSET($B$101,$B37,$C37),0) -> 0
A38: =IF(AND(B38<=$K$1,C38<=$K$1),B38*10+C38,0) -> 0 | B38: 3 | C38: 8 | D38: =IF(OR(B38=B37,A38=0),"",VLOOKUP($B38,$A$6:$D$15,2)) | H38: =IF(B38>0,VLOOKUP($C38,$A$6:$D$15,2),"") | M38: =IF(AND(P38<>0,L$66>=($K$1*($K$1-1)/2)),RANK(P38,P$21:P$65),"") | N38: =IF(M38<4,OFFSET($B$123,$B38,$C38),"") | O38: =IF(AND(L38<>"",K38<>""),L38^(IF(K38="a",1,-1)),1) -> 1 | P38: =IF(AND($M$17>=$K$17,$A38>0),OFFSET($B$101,$B38,$C38),0) -> 0
A39: =IF(AND(B39<=$K$1,C39<=$K$1),B39*10+C39,0) -> 0 | B39: 4 | C39: 5 | D39: =IF(OR(B39=B38,A39=0),"",VLOOKUP($B39,$A$6:$D$15,2)) | H39: =IF(B39>0,VLOOKUP($C39,$A$6:$D$15,2),"") | M39: =IF(AND(P39<>0,L$66>=($K$1*($K$1-1)/2)),RANK(P39,P$21:P$65),"") | N39: =IF(M39<4,OFFSET($B$123,$B39,$C39),"") | O39: =IF(AND(L39<>"",K39<>""),L39^(IF(K39="a",1,-1)),1) -> 1 | P39: =IF(AND($M$17>=$K$17,$A39>0),OFFSET($B$101,$B39,$C39),0) -> 0
A40: =IF(AND(B40<=$K$1,C40<=$K$1),B40*10+C40,0) -> 0 | B40: 4 | C40: 6 | D40: =IF(OR(B40=B39,A40=0),"",VLOOKUP($B40,$A$6:$D$15,2)) | H40: =IF(B40>0,VLOOKUP($C40,$A$6:$D$15,2),"") | M40: =IF(AND(P40<>0,L$66>=($K$1*($K$1-1)/2)),RANK(P40,P$21:P$65),"") | N40: =IF(M40<4,OFFSET($B$123,$B40,$C40),"") | O40: =IF(AND(L40<>"",K40<>""),L40^(IF(K40="a",1,-1)),1) -> 1 | P40: =IF(AND($M$17>=$K$17,$A40>0),OFFSET($B$101,$B40,$C40),0) -> 0
... A65: =IF(AND(B65<=$K$1,C65<=$K$1),B65*10+C65,0) -> 0 | B65: 9 | C65: 10 | D65: =IF(OR(B65=B64,A65=0),"",VLOOKUP($B65,$A$6:$D$15,2)) | H65: =IF(B65>0,VLOOKUP($C65,$A$6:$D$15,2),"") | M65: =IF(AND(P65<>0,L$66>=($K$1*($K$1-1)/2)),RANK(P65,P$21:P$65),"") | N65: =IF(M65<4,OFFSET($B$123,$B65,$C65),"") | O65: =IF(AND(L65<>"",K65<>""),L65^(IF(K65="a",1,-1)),1) -> 1 | P65: =IF(AND($M$17>=$K$17,$A65>0),OFFSET($B$101,$B65,$C65),0) -> 0
K66: =COUNT(K21:K65) -> 0 | L66: =COUNT(L21:L65) -> 3
A67: Intensity of importance | D67: Definition | G67: Explanation
...

Sheet In3
A1: AHP Analytic Hierarchy Process | J1: n= | K1: =Summary!B5 -> 3 | N1: Input | O1: 3
A2: Objective: | D2: =Summary!B11 -> Comparing Smoothness Factor Among Conventional Checkout, Self-Checkout and Unmanned Shop
A5: n | B5: Criteria | G5: Comment | O5: RGMM | P5: +/-
A6: 1 | B6: =IF(ISBLANK(Summary!C18),"",Summary!C18) -> Conventional Cashier | G6: =IF(ISBLANK(Summary!F18),"",Summary!F18) | O6: =O91/O$101 -> 0.54994561 | P6: =N91*SINH(P79)/O$101 -> 0.073878621
A7: 2 | B7: =IF(ISBLANK(Summary!C19),"",Summary!C19) -> Self-Checkout | G7: =IF(ISBLANK(Summary!F19),"",Summary!F19) | O7: =O92/O$101 -> 0.20984352 | P7: =N92*SINH(P80)/O$101 -> 0.02818997
A8: 3 | B8: =IF(ISBLANK(Summary!C20),"",Summary!C20) -> Unmanned Shop | G8: =IF(ISBLANK(Summary!F20),"",Summary!F20) | O8: =O93/O$101 -> 0.24021087 | P8: =N93*SINH(P81)/O$101 -> 0.03226946
A9: 4 | B9: =IF(ISBLANK(Summary!C21),"",Summary!C21) | G9: =IF(ISBLANK(Summary!F21),"",Summary!F21) | O9: =O94/O$101 -> 0 | P9: =N94*SINH(P82)/O$101 -> 0
A10: 5 | B10: =IF(ISBLANK(Summary!C22),"",Summary!C22) | G10: =IF(ISBLANK(Summary!F22),"",Summary!F22) | O10: =O95/O$101 -> 0 | P10: =N95*SINH(P83)/O$101 -> 0
A11: 6 | B11: =IF(ISBLANK(Summary!C23),"",Summary!C23) | G11: =IF(ISBLANK(Summary!F23),"",Summary!F23) | O11: =O96/O$101 -> 0 | P11: =N96*SINH(P84)/O$101 -> 0
A12: 7 | B12: =IF(ISBLANK(Summary!C24),"",Summary!C24) | G12: =IF(ISBLANK(Summary!F24),"",Summary!F24) | O12: =O97/O$101 -> 0 | P12: =N97*SINH(P85)/O$101 -> 0
A13: 8 | B13: =IF(ISBLANK(Summary!C25),"",Summary!C25) | G13: =IF(ISBLANK(Summary!F25),"",Summary!F25) | O13: =O98/O$101 -> 0 | P13: =N98*SINH(P86)/O$101 -> 0
A14: 9 | B14: =IF(ISBLANK(Summary!C26),"",Summary!C26) | G14: =IF(ISBLANK(Summary!F26),"",Summary!F26) -> for 9&10 unprotect the input sheets and expand the | O14: =O99/O$101 -> 0 | P14: =N99*SINH(P87)/O$101 -> 0
A15: 10 | B15: =IF(ISBLANK(Summary!C27),"",Summary!C27) | G15: =IF(ISBLANK(Summary!F27),"",Summary!F27) -> question section ("+" in row 66) | O15: =O100/O$101 -> 0 | P15: =N100*SINH(P88)/O$101 -> 0
B17: Participant 3 | F17: 1 | J17: a: | K17: =Summary!K7 -> 0.1 | L17: CR: | M17: =(N101-K1)/((2.7699*K1-4.3513)-K1) -> 0.019088801 | O17: =Summary!K5 -> 1
B18: Name | F18: Weight | H18: Date | M18: Consistency Ratio
G19: Criteria | K19: more important ? | L19: Scale | O19: A
B20: i | C20: j | D20: A | H20: B | K20: - A or B | L20: (1-9) | O20: B
